Workbook

Sheet Cấu hình
A1: CẤU HÌNH TÍNH CHI PHÍ / 成本计算设置
A2: Phút/ngày/người dùng / 每位用户每天分钟数 | B2: 10 | C2: Ô nhập chính / 主要输入
A3: Số ngày/tháng / 每月天数 | B3: 30 | C3: Giả định thời gian / 时间假设
A4: Tỷ giá VND/USD / 越南盾/美元汇率 | B4: 26000 | C4: Dùng để quy đổi VND / 用于换算越南盾
A6: CLOUDFLARE WORKERS AI — GIẢ ĐỊNH / 假设
A7: Neurons/phút audio / 每分钟音频 Neurons | B7: 46.63 | C7: Theo số liệu đang dùng trong báo cáo gốc / 沿用原报告参数
A8: Quota miễn phí/ngày / 每日免费额度 | B8: 10000 | C8: Neurons/ngày / Neurons/天
A9: Workers Paid tối thiểu/tháng / 最低月费 | B9: 5 | C9: USD; chỉ cộng khi vượt quota ngày / 超过每日额度时计入
A10: Phí vượt quota / 超额费用 | B10: 0.011 | C10: USD/1.000 Neurons
A12: VERTEX AI CUSTOM ENDPOINT — GIẢ ĐỊNH / 假设
A13: Chi phí/giờ/replica / 每小时每副本成本 | B13: 0.621 | C13: USD/giờ / 美元/小时
A14: Số giờ chạy/tháng / 每月运行小时 | B14: 730 | C14: Replica warm chạy 24/7 / 热副本全天候运行
A15: Công suất lạc quan / 乐观容量 | B15: 5000 | C15: Giờ audio/tháng/replica / 音频小时/月/副本
A16: Công suất thận trọng / 保守容量 | B16: 2500 | C16: Giờ audio/tháng/replica / 音频小时/月/副本
A18: Cách dùng / 使用方法
A19: Ví dụ: đổi B3 từ 10 thành 12. Phút/tháng, giờ audio, chi phí USD và quy đổi VND sẽ cập nhật tự động.
A20: 示例：将 B3 从 10 改为 12。每月分钟数、音频小时数、美元成本和越南盾换算都会自动更新。

Sheet Trang tính2
A1: Triển khai Model AI Cloudflare hay Vertex AI? 部署 AI 模型：选择 Cloudflare 还是 Vertex AI？
A2: ="Chi phí khi mỗi người dùng nói và sử dụng trợ lí "&'Cấu hình'!$B$2&" phút mỗi ngày (đổi tại Cấu hình!B3)"&CHAR(10)&"每位用户每天使用助手 "&'Cấu hình'!$B$2&" 分钟的费用（在 Cấu hình!B3 修改）。" -> Chi phí khi mỗi người dùng nói và sử dụng trợ lí 10 phút mỗi ngày (đổi tại Cấu hình!B3) 每位用户每天使用助手 10 分钟的费用（在 Cấu hình!B3 修改）。
A3: KẾT LUẬN: 结论： Từ 1 đến 1.000 user, Cloudflare là lựa chọn mặc định: rẻ hơn, triển khai nhanh và không phải vận hành GPU. 在 1 至 1,000 名用户的范围内，默认推荐 Cloudflare：成本更低、部署更快，并且无需运维 GPU。 Chỉ chuyển sang Vertex AI khi model tùy biến tạo ra lợi ích chất lượng rõ rệt, có yêu cầu IAM/VPC của GCP, hoặc benchmark thực tế chứng minh tổng chi phí thấp hơn. 只有在自定义模型能够显著提升质量、必须使用 GCP 的 IAM/VPC，或实际基准测试证明总成本更低时，才切换到 Vertex AI。
A4: 不同用户规模的成本
A5: Giải pháp 方案 | B5: User 用户数 | C5: Phút/tháng 分钟/月 | D5: Tổng USD 合计（美元） | E5: Quy đổi VND 折合越南盾
A6: Cloudflare Workers AI Cloudflare Workers AI 方案 | B6: 1 | C6: =B6*'Cấu hình'!$B$2*'Cấu hình'!$B$3 -> 300 | D6: =IF(B6*'Cấu hình'!$B$2*'Cấu hình'!$B$7<='Cấu hình'!$B$8,0,'Cấu hình'!$B$9+(B6*'Cấu hình'!$B$2*'Cấu hình'!$B$7-'Cấu hình'!$B$8)*'Cấu hình'!$B$3*'Cấu hình'!$B$10/1000) -> 0 | E6: =D6*'Cấu hình'!$B$4 -> 0
B7: 100 | C7: =B7*'Cấu hình'!$B$2*'Cấu hình'!$B$3 -> 30000 | D7: =IF(B7*'Cấu hình'!$B$2*'Cấu hình'!$B$7<='Cấu hình'!$B$8,0,'Cấu hình'!$B$9+(B7*'Cấu hình'!$B$2*'Cấu hình'!$B$7-'Cấu hình'!$B$8)*'Cấu hình'!$B$3*'Cấu hình'!$B$10/1000) -> 17.0879 | E7: =D7*'Cấu hình'!$B$4 -> 444285.4
B8: 500 | C8: =B8*'Cấu hình'!$B$2*'Cấu hình'!$B$3 -> 150000 | D8: =IF(B8*'Cấu hình'!$B$2*'Cấu hình'!$B$7<='Cấu hình'!$B$8,0,'Cấu hình'!$B$9+(B8*'Cấu hình'!$B$2*'Cấu hình'!$B$7-'Cấu hình'!$B$8)*'Cấu hình'!$B$3*'Cấu hình'!$B$10/1000) -> 78.6395 | E8: =D8*'Cấu hình'!$B$4 -> 2044627
B9: 1000 | C9: =B9*'Cấu hình'!$B$2*'Cấu hình'!$B$3 -> 300000 | D9: =IF(B9*'Cấu hình'!$B$2*'Cấu hình'!$B$7<='Cấu hình'!$B$8,0,'Cấu hình'!$B$9+(B9*'Cấu hình'!$B$2*'Cấu hình'!$B$7-'Cấu hình'!$B$8)*'Cấu hình'!$B$3*'Cấu hình'!$B$10/1000) -> 155.579 | E9: =D9*'Cấu hình'!$B$4 -> 4045054
B10: 2000 | C10: =B10*'Cấu hình'!$B$2*'Cấu hình'!$B$3 -> 600000 | D10: =IF(B10*'Cấu hình'!$B$2*'Cấu hình'!$B$7<='Cấu hình'!$B$8,0,'Cấu hình'!$B$9+(B10*'Cấu hình'!$B$2*'Cấu hình'!$B$7-'Cấu hình'!$B$8)*'Cấu hình'!$B$3*'Cấu hình'!$B$10/1000) -> 309.458 | E10: =D10*'Cấu hình'!$B$4 -> 8045908
B11: 3000 | C11: =B11*'Cấu hình'!$B$2*'Cấu hình'!$B$3 -> 900000 | D11: =IF(B11*'Cấu hình'!$B$2*'Cấu hình'!$B$7<='Cấu hình'!$B$8,0,'Cấu hình'!$B$9+(B11*'Cấu hình'!$B$2*'Cấu hình'!$B$7-'Cấu hình'!$B$8)*'Cấu hình'!$B$3*'Cấu hình'!$B$10/1000) -> 463.337 | E11: =D11*'Cấu hình'!$B$4 -> 12046762
B12: 5000 | C12: =B12*'Cấu hình'!$B$2*'Cấu hình'!$B$3 -> 1500000 | D12: =IF(B12*'Cấu hình'!$B$2*'Cấu hình'!$B$7<='Cấu hình'!$B$8,0,'Cấu hình'!$B$9+(B12*'Cấu hình'!$B$2*'Cấu hình'!$B$7-'Cấu hình'!$B$8)*'Cấu hình'!$B$3*'Cấu hình'!$B$10/1000) -> 771.095 | E12: =D12*'Cấu hình'!$B$4 -> 20048470
A13: Vertex AI Vertex AI 方案 | B13: 1 | C13: =B13*'Cấu hình'!$B$2*'Cấu hình'!$B$3 -> 300 | D13: =IF(MAX(1,ROUNDUP(C13/60/'Cấu hình'!$B$15,0))=MAX(1,ROUNDUP(C13/60/'Cấu hình'!$B$16,0)),TEXT(MAX(1,ROUNDUP(C13/60/'Cấu hình'!$B$15,0))*'Cấu hình'!$B$13*'Cấu hình'!$B$14,"$#,##0.00"),TEXT(MAX(1,ROUNDUP(C13/60/'Cấu hình'!$B$15,0))*'Cấu hình'!$B$13*'Cấu hình'!$B$14,"#,##0.00")&"–"&TEXT(MAX(1,ROUNDUP(C13/60/'Cấu hình'!$B$16,0))*'Cấu hình'!$B$13*'Cấu hình'!$B$14,"#,##0.00")) -> $453.33 | E13: =IF(MAX(1,ROUNDUP(C13/60/'Cấu hình'!$B$15,0))=MAX(1,ROUNDUP(C13/60/'Cấu hình'!$B$16,0)),TEXT(MAX(1,ROUNDUP(C13/60/'Cấu hình'!$B$15,0))*'Cấu hình'!$B$13*'Cấu hình'!$B$14*'Cấu hình'!$B$4/1000000,"0.00")&" triệu",TEXT(MAX(1,ROUNDUP(C13/60/'Cấu hình'!$B$15,0))*'Cấu hình'!$B$13*'Cấu hình'!$B$14*'Cấu hình'!$B$4/1000000,"0.00")&"–"&TEXT(MAX(1,ROUNDUP(C13/60/'Cấu hình'!$B$16,0))*'Cấu hình'!$B$13*'Cấu hình'!$B$14*'Cấu hình'!$B$4/1000000,"0.00")&" triệu") -> 11.79 triệu
B14: 100 | C14: =B14*'Cấu hình'!$B$2*'Cấu hình'!$B$3 -> 30000 | D14: =IF(MAX(1,ROUNDUP(C14/60/'Cấu hình'!$B$15,0))=MAX(1,ROUNDUP(C14/60/'Cấu hình'!$B$16,0)),TEXT(MAX(1,ROUNDUP(C14/60/'Cấu hình'!$B$15,0))*'Cấu hình'!$B$13*'Cấu hình'!$B$14,"$#,##0.00"),TEXT(MAX(1,ROUNDUP(C14/60/'Cấu hình'!$B$15,0))*'Cấu hình'!$B$13*'Cấu hình'!$B$14,"#,##0.00")&"–"&TEXT(MAX(1,ROUNDUP(C14/60/'Cấu hình'!$B$16,0))*'Cấu hình'!$B$13*'Cấu hình'!$B$14,"#,##0.00")) -> $453.33 | E14: =IF(MAX(1,ROUNDUP(C14/60/'Cấu hình'!$B$15,0))=MAX(1,ROUNDUP(C14/60/'Cấu hình'!$B$16,0)),TEXT(MAX(1,ROUNDUP(C14/60/'Cấu hình'!$B$15,0))*'Cấu hình'!$B$13*'Cấu hình'!$B$14*'Cấu hình'!$B$4/1000000,"0.00")&" triệu",TEXT(MAX(1,ROUNDUP(C14/60/'Cấu hình'!$B$15,0))*'Cấu hình'!$B$13*'Cấu hình'!$B$14*'Cấu hình'!$B$4/1000000,"0.00")&"–"&TEXT(MAX(1,ROUNDUP(C14/60/'Cấu hình'!$B$16,0))*'Cấu hình'!$B$13*'Cấu hình'!$B$14*'Cấu hình'!$B$4/1000000,"0.00")&" triệu") -> 11.79 triệu
B15: 500 | C15: =B15*'Cấu hình'!$B$2*'Cấu hình'!$B$3 -> 150000 | D15: =IF(MAX(1,ROUNDUP(C15/60/'Cấu hình'!$B$15,0))=MAX(1,ROUNDUP(C15/60/'Cấu hình'!$B$16,0)),TEXT(MAX(1,ROUNDUP(C15/60/'Cấu hình'!$B$15,0))*'Cấu hình'!$B$13*'Cấu hình'!$B$14,"$#,##0.00"),TEXT(MAX(1,ROUNDUP(C15/60/'Cấu hình'!$B$15,0))*'Cấu hình'!$B$13*'Cấu hình'!$B$14,"#,##0.00")&"–"&TEXT(MAX(1,ROUNDUP(C15/60/'Cấu hình'!$B$16,0))*'Cấu hình'!$B$13*'Cấu hình'!$B$14,"#,##0.00")) -> $453.33 | E15: =IF(MAX(1,ROUNDUP(C15/60/'Cấu hình'!$B$15,0))=MAX(1,ROUNDUP(C15/60/'Cấu hình'!$B$16,0)),TEXT(MAX(1,ROUNDUP(C15/60/'Cấu hình'!$B$15,0))*'Cấu hình'!$B$13*'Cấu hình'!$B$14*'Cấu hình'!$B$4/1000000,"0.00")&" triệu",TEXT(MAX(1,ROUNDUP(C15/60/'Cấu hình'!$B$15,0))*'Cấu hình'!$B$13*'Cấu hình'!$B$14*'Cấu hình'!$B$4/1000000,"0.00")&"–"&TEXT(MAX(1,ROUNDUP(C15/60/'Cấu hình'!$B$16,0))*'Cấu hình'!$B$13*'Cấu hình'!$B$14*'Cấu hình'!$B$4/1000000,"0.00")&" triệu") -> 11.79 triệu
B16: 1000 | C16: =B16*'Cấu hình'!$B$2*'Cấu hình'!$B$3 -> 300000 | D16: =IF(MAX(1,ROUNDUP(C16/60/'Cấu hình'!$B$15,0))=MAX(1,ROUNDUP(C16/60/'Cấu hình'!$B$16,0)),TEXT(MAX(1,ROUNDUP(C16/60/'Cấu hình'!$B$15,0))*'Cấu hình'!$B$13*'Cấu hình'!$B$14,"$#,##0.00"),TEXT(MAX(1,ROUNDUP(C16/60/'Cấu hình'!$B$15,0))*'Cấu hình'!$B$13*'Cấu hình'!$B$14,"#,##0.00")&"–"&TEXT(MAX(1,ROUNDUP(C16/60/'Cấu hình'!$B$16,0))*'Cấu hình'!$B$13*'Cấu hình'!$B$14,"#,##0.00")) -> 453.33–906.66 | E16: =IF(MAX(1,ROUNDUP(C16/60/'Cấu hình'!$B$15,0))=MAX(1,ROUNDUP(C16/60/'Cấu hình'!$B$16,0)),TEXT(MAX(1,ROUNDUP(C16/60/'Cấu hình'!$B$15,0))*'Cấu hình'!$B$13*'Cấu hình'!$B$14*'Cấu hình'!$B$4/1000000,"0.00")&" triệu",TEXT(MAX(1,ROUNDUP(C16/60/'Cấu hình'!$B$15,0))*'Cấu hình'!$B$13*'Cấu hình'!$B$14*'Cấu hình'!$B$4/1000000,"0.00")&"–"&TEXT(MAX(1,ROUNDUP(C16/60/'Cấu hình'!$B$16,0))*'Cấu hình'!$B$13*'Cấu hình'!$B$14*'Cấu hình'!$B$4/1000000,"0.00")&" triệu") -> 11.79–23.57 triệu
B17: 2000 | C17: =B17*'Cấu hình'!$B$2*'Cấu hình'!$B$3 -> 600000 | D17: =IF(MAX(1,ROUNDUP(C17/60/'Cấu hình'!$B$15,0))=MAX(1,ROUNDUP(C17/60/'Cấu hình'!$B$16,0)),TEXT(MAX(1,ROUNDUP(C17/60/'Cấu hình'!$B$15,0))*'Cấu hình'!$B$13*'Cấu hình'!$B$14,"$#,##0.00"),TEXT(MAX(1,ROUNDUP(C17/60/'Cấu hình'!$B$15,0))*'Cấu hình'!$B$13*'Cấu hình'!$B$14,"#,##0.00")&"–"&TEXT(MAX(1,ROUNDUP(C17/60/'Cấu hình'!$B$16,0))*'Cấu hình'!$B$13*'Cấu hình'!$B$14,"#,##0.00")) -> 906.66–1,813.32 | E17: =IF(MAX(1,ROUNDUP(C17/60/'Cấu hình'!$B$15,0))=MAX(1,ROUNDUP(C17/60/'Cấu hình'!$B$16,0)),TEXT(MAX(1,ROUNDUP(C17/60/'Cấu hình'!$B$15,0))*'Cấu hình'!$B$13*'Cấu hình'!$B$14*'Cấu hình'!$B$4/1000000,"0.00")&" triệu",TEXT(MAX(1,ROUNDUP(C17/60/'Cấu hình'!$B$15,0))*'Cấu hình'!$B$13*'Cấu hình'!$B$14*'Cấu hình'!$B$4/1000000,"0.00")&"–"&TEXT(MAX(1,ROUNDUP(C17/60/'Cấu hình'!$B$16,0))*'Cấu hình'!$B$13*'Cấu hình'!$B$14*'Cấu hình'!$B$4/1000000,"0.00")&" triệu") -> 23.57–47.15 triệu
B18: 3000 | C18: =B18*'Cấu hình'!$B$2*'Cấu hình'!$B$3 -> 900000 | D18: =IF(MAX(1,ROUNDUP(C18/60/'Cấu hình'!$B$15,0))=MAX(1,ROUNDUP(C18/60/'Cấu hình'!$B$16,0)),TEXT(MAX(1,ROUNDUP(C18/60/'Cấu hình'!$B$15,0))*'Cấu hình'!$B$13*'Cấu hình'!$B$14,"$#,##0.00"),TEXT(MAX(1,ROUNDUP(C18/60/'Cấu hình'!$B$15,0))*'Cấu hình'!$B$13*'Cấu hình'!$B$14,"#,##0.00")&"–"&TEXT(MAX(1,ROUNDUP(C18/60/'Cấu hình'!$B$16,0))*'Cấu hình'!$B$13*'Cấu hình'!$B$14,"#,##0.00")) -> 1,359.99–2,719.98 | E18: =IF(MAX(1,ROUNDUP(C18/60/'Cấu hình'!$B$15,0))=MAX(1,ROUNDUP(C18/60/'Cấu hình'!$B$16,0)),TEXT(MAX(1,ROUNDUP(C18/60/'Cấu hình'!$B$15,0))*'Cấu hình'!$B$13*'Cấu hình'!$B$14*'Cấu hình'!$B$4/1000000,"0.00")&" triệu",TEXT(MAX(1,ROUNDUP(C18/60/'Cấu hình'!$B$15,0))*'Cấu hình'!$B$13*'Cấu hình'!$B$14*'Cấu hình'!$B$4/1000000,"0.00")&"–"&TEXT(MAX(1,ROUNDUP(C18/60/'Cấu hình'!$B$16,0))*'Cấu hình'!$B$13*'Cấu hình'!$B$14*'Cấu hình'!$B$4/1000000,"0.00")&" triệu") -> 35.36–70.72 triệu
B19: 5000 | C19: =B19*'Cấu hình'!$B$2*'Cấu hình'!$B$3 -> 1500000 | D19: =IF(MAX(1,ROUNDUP(C19/60/'Cấu hình'!$B$15,0))=MAX(1,ROUNDUP(C19/60/'Cấu hình'!$B$16,0)),TEXT(MAX(1,ROUNDUP(C19/60/'Cấu hình'!$B$15,0))*'Cấu hình'!$B$13*'Cấu hình'!$B$14,"$#,##0.00"),TEXT(MAX(1,ROUNDUP(C19/60/'Cấu hình'!$B$15,0))*'Cấu hình'!$B$13*'Cấu hình'!$B$14,"#,##0.00")&"–"&TEXT(MAX(1,ROUNDUP(C19/60/'Cấu hình'!$B$16,0))*'Cấu hình'!$B$13*'Cấu hình'!$B$14,"#,##0.00")) -> 2,266.65–4,533.30 | E19: =IF(MAX(1,ROUNDUP(C19/60/'Cấu hình'!$B$15,0))=MAX(1,ROUNDUP(C19/60/'Cấu hình'!$B$16,0)),TEXT(MAX(1,ROUNDUP(C19/60/'Cấu hình'!$B$15,0))*'Cấu hình'!$B$13*'Cấu hình'!$B$14*'Cấu hình'!$B$4/1000000,"0.00")&" triệu",TEXT(MAX(1,ROUNDUP(C19/60/'Cấu hình'!$B$15,0))*'Cấu hình'!$B$13*'Cấu hình'!$B$14*'Cấu hình'!$B$4/1000000,"0.00")&"–"&TEXT(MAX(1,ROUNDUP(C19/60/'Cấu hình'!$B$16,0))*'Cấu hình'!$B$13*'Cấu hình'!$B$14*'Cấu hình'!$B$4/1000000,"0.00")&" triệu") -> 58.93–117.87 triệu
A21: 1. Cloudflare Workers AI
A23: ĐƠN GIÁ:
A24: 计价说明：
A25: ="Mỗi user dùng "&TEXT('Cấu hình'!$B$2*'Cấu hình'!$B$7,"0.0")&" Neurons/ngày." -> Mỗi user dùng 466.3 Neurons/ngày.
A26: ="每位用户每天使用 "&TEXT('Cấu hình'!$B$2*'Cấu hình'!$B$7,"0.0")&" Neurons。" -> 每位用户每天使用 466.3 Neurons。
A27: ="Chi phí AI tháng = max(0; "&TEXT('Cấu hình'!$B$2*'Cấu hình'!$B$7,"0.0")&" x số user - "&TEXT('Cấu hình'!$B$8,"#,##0")&") x "&TEXT('Cấu hình'!$B$3,"0")&" x "&TEXT('Cấu hình'!$B$10,"0.000")&" / 1.000." -> Chi phí AI tháng = max(0; 466.3 x số user - 10,000) x 30 x 0.011 / 1.000.
A28: ="每月 AI 成本 = max(0；"&TEXT('Cấu hình'!$B$2*'Cấu hình'!$B$7,"0.0")&" × 用户数 - "&TEXT('Cấu hình'!$B$8,"#,##0")&") × "&TEXT('Cấu hình'!$B$3,"0")&" × "&TEXT('Cấu hình'!$B$10,"0.000")&" / 1,000。" -> 每月 AI 成本 = max(0；466.3 × 用户数 - 10,000) × 30 × 0.011 / 1,000。
A29: ="Khi vượt quota ngày, cộng tối thiểu "&TEXT('Cấu hình'!$B$9,"0.00")&" USD/tháng cho Workers Paid." -> Khi vượt quota ngày, cộng tối thiểu 5.00 USD/tháng cho Workers Paid.
A30: ="当每日用量超过免费额度时，需要至少支付每月 "&TEXT('Cấu hình'!$B$9,"0.00")&" 美元的 Workers Paid 套餐费。" -> 当每日用量超过免费额度时，需要至少支付每月 5.00 美元的 Workers Paid 套餐费。
A31: ="Nếu vượt quota Workers Paid, AI được tính riêng ở mức $"&TEXT('Cấu hình'!$B$10,"0.000")&"/1.000 Neurons." -> Nếu vượt quota Workers Paid, AI được tính riêng ở mức $0.011/1.000 Neurons.
A32: ="使用 Workers Paid 后，超出免费额度的 AI 用量按每 1,000 Neurons "&TEXT('Cấu hình'!$B$10,"0.000")&" 美元另行计费。" -> 使用 Workers Paid 后，超出免费额度的 AI 用量按每 1,000 Neurons 0.011 美元另行计费。
A34: User 用户数 | B34: Phút/tháng 分钟/月 | C34: Tổng USD 合计（美元） | D34: Quy đổi VND 折合越南盾
A35: 1 | B35: =A35*'Cấu hình'!$B$2*'Cấu hình'!$B$3 -> 300 | C35: =IF(A35*'Cấu hình'!$B$2*'Cấu hình'!$B$7<='Cấu hình'!$B$8,0,'Cấu hình'!$B$9+(A35*'Cấu hình'!$B$2*'Cấu hình'!$B$7-'Cấu hình'!$B$8)*'Cấu hình'!$B$3*'Cấu hình'!$B$10/1000) -> 0 | D35: =C35*'Cấu hình'!$B$4 -> 0
A36: 100 | B36: =A36*'Cấu hình'!$B$2*'Cấu hình'!$B$3 -> 30000 | C36: =IF(A36*'Cấu hình'!$B$2*'Cấu hình'!$B$7<='Cấu hình'!$B$8,0,'Cấu hình'!$B$9+(A36*'Cấu hình'!$B$2*'Cấu hình'!$B$7-'Cấu hình'!$B$8)*'Cấu hình'!$B$3*'Cấu hình'!$B$10/1000) -> 17.0879 | D36: =C36*'Cấu hình'!$B$4 -> 444285.4
A37: 500 | B37: =A37*'Cấu hình'!$B$2*'Cấu hình'!$B$3 -> 150000 | C37: =IF(A37*'Cấu hình'!$B$2*'Cấu hình'!$B$7<='Cấu hình'!$B$8,0,'Cấu hình'!$B$9+(A37*'Cấu hình'!$B$2*'Cấu hình'!$B$7-'Cấu hình'!$B$8)*'Cấu hình'!$B$3*'Cấu hình'!$B$10/1000) -> 78.6395 | D37: =C37*'Cấu hình'!$B$4 -> 2044627
A38: 1000 | B38: =A38*'Cấu hình'!$B$2*'Cấu hình'!$B$3 -> 300000 | C38: =IF(A38*'Cấu hình'!$B$2*'Cấu hình'!$B$7<='Cấu hình'!$B$8,0,'Cấu hình'!$B$9+(A38*'Cấu hình'!$B$2*'Cấu hình'!$B$7-'Cấu hình'!$B$8)*'Cấu hình'!$B$3*'Cấu hình'!$B$10/1000) -> 155.579 | D38: =C38*'Cấu hình'!$B$4 -> 4045054
A39: 2000 | B39: =A39*'Cấu hình'!$B$2*'Cấu hình'!$B$3 -> 600000 | C39: =IF(A39*'Cấu hình'!$B$2*'Cấu hình'!$B$7<='Cấu hình'!$B$8,0,'Cấu hình'!$B$9+(A39*'Cấu hình'!$B$2*'Cấu hình'!$B$7-'Cấu hình'!$B$8)*'Cấu hình'!$B$3*'Cấu hình'!$B$10/1000) -> 309.458 | D39: =C39*'Cấu hình'!$B$4 -> 8045908
A40: 3000 | B40: =A40*'Cấu hình'!$B$2*'Cấu hình'!$B$3 -> 900000 | C40: =IF(A40*'Cấu hình'!$B$2*'Cấu hình'!$B$7<='Cấu hình'!$B$8,0,'Cấu hình'!$B$9+(A40*'Cấu hình'!$B$2*'Cấu hình'!$B$7-'Cấu hình'!$B$8)*'Cấu hình'!$B$3*'Cấu hình'!$B$10/1000) -> 463.337 | D40: =C40*'Cấu hình'!$B$4 -> 12046762
A41: 5000 | B41: =A41*'Cấu hình'!$B$2*'Cấu hình'!$B$3 -> 1500000 | C41: =IF(A41*'Cấu hình'!$B$2*'Cấu hình'!$B$7<='Cấu hình'!$B$8,0,'Cấu hình'!$B$9+(A41*'Cấu hình'!$B$2*'Cấu hình'!$B$7-'Cấu hình'!$B$8)*'Cấu hình'!$B$3*'Cấu hình'!$B$10/1000) -> 771.095 | D41: =C41*'Cấu hình'!$B$4 -> 20048470
A44: 2. Vertex AI custom endpoint
A45: 2. Vertex AI 自定义端点
...
