Workbook

Sheet Tong quan
A1: TỔNG QUAN NGHIỆM THU AIV1 | B1: TỔNG QUAN NGHIỆM THU AIV1 | C1: TỔNG QUAN NGHIỆM THU AIV1 | D1: TỔNG QUAN NGHIỆM THU AIV1 | E1: TỔNG QUAN NGHIỆM THU AIV1 | F1: TỔNG QUAN NGHIỆM THU AIV1 | G1: TỔNG QUAN NGHIỆM THU AIV1
A2: Bảng điều khiển tự động dựa trên Result trong sheet Test Cases. Đây là công cụ hỗ trợ; quyết định cuối cần biên bản và chữ ký có thẩm quyền. | B2: Bảng điều khiển tự động dựa trên Result trong sheet Test Cases. Đây là công cụ hỗ trợ; quyết định cuối cần biên bản và chữ ký có thẩm quyền. | C2: Bảng điều khiển tự động dựa trên Result trong sheet Test Cases. Đây là công cụ hỗ trợ; quyết định cuối cần biên bản và chữ ký có thẩm quyền. | D2: Bảng điều khiển tự động dựa trên Result trong sheet Test Cases. Đây là công cụ hỗ trợ; quyết định cuối cần biên bản và chữ ký có thẩm quyền. | E2: Bảng điều khiển tự động dựa trên Result trong sheet Test Cases. Đây là công cụ hỗ trợ; quyết định cuối cần biên bản và chữ ký có thẩm quyền. | F2: Bảng điều khiển tự động dựa trên Result trong sheet Test Cases. Đây là công cụ hỗ trợ; quyết định cuối cần biên bản và chữ ký có thẩm quyền. | G2: Bảng điều khiển tự động dựa trên Result trong sheet Test Cases. Đây là công cụ hỗ trợ; quyết định cuối cần biên bản và chữ ký có thẩm quyền.
A4: Tình trạng thực thi theo mức độ | B4: Tình trạng thực thi theo mức độ | C4: Tình trạng thực thi theo mức độ | D4: Tình trạng thực thi theo mức độ | E4: Tình trạng thực thi theo mức độ | F4: Tình trạng thực thi theo mức độ | G4: Tình trạng thực thi theo mức độ
A5: Mức | B5: Tổng | C5: Chưa test | D5: Đạt | E5: Đạt có điều kiện | F5: Không đạt | G5: Không áp dụng
A6: P0 | B6: =COUNTIF('Test Cases'!$G$7:$G$175,$A6) -> 123 | C6: =COUNTIFS('Test Cases'!$G$7:$G$175,$A6,'Test Cases'!$O$7:$O$175,C$5) -> 123 | D6: =COUNTIFS('Test Cases'!$G$7:$G$175,$A6,'Test Cases'!$O$7:$O$175,D$5) -> 0 | E6: =COUNTIFS('Test Cases'!$G$7:$G$175,$A6,'Test Cases'!$O$7:$O$175,E$5) -> 0 | F6: =COUNTIFS('Test Cases'!$G$7:$G$175,$A6,'Test Cases'!$O$7:$O$175,F$5) -> 0 | G6: =COUNTIFS('Test Cases'!$G$7:$G$175,$A6,'Test Cases'!$O$7:$O$175,"Không áp dụng (Tương lai)") -> 0
A7: P1 | B7: =COUNTIF('Test Cases'!$G$7:$G$175,$A7) -> 39 | C7: =COUNTIFS('Test Cases'!$G$7:$G$175,$A7,'Test Cases'!$O$7:$O$175,C$5) -> 39 | D7: =COUNTIFS('Test Cases'!$G$7:$G$175,$A7,'Test Cases'!$O$7:$O$175,D$5) -> 0 | E7: =COUNTIFS('Test Cases'!$G$7:$G$175,$A7,'Test Cases'!$O$7:$O$175,E$5) -> 0 | F7: =COUNTIFS('Test Cases'!$G$7:$G$175,$A7,'Test Cases'!$O$7:$O$175,F$5) -> 0 | G7: =COUNTIFS('Test Cases'!$G$7:$G$175,$A7,'Test Cases'!$O$7:$O$175,"Không áp dụng (Tương lai)") -> 0
A8: Tương lai | B8: =COUNTIF('Test Cases'!$G$7:$G$175,$A8) -> 7 | C8: =COUNTIFS('Test Cases'!$G$7:$G$175,$A8,'Test Cases'!$O$7:$O$175,C$5) -> 0 | D8: =COUNTIFS('Test Cases'!$G$7:$G$175,$A8,'Test Cases'!$O$7:$O$175,D$5) -> 0 | E8: =COUNTIFS('Test Cases'!$G$7:$G$175,$A8,'Test Cases'!$O$7:$O$175,E$5) -> 0 | F8: =COUNTIFS('Test Cases'!$G$7:$G$175,$A8,'Test Cases'!$O$7:$O$175,F$5) -> 0 | G8: =COUNTIFS('Test Cases'!$G$7:$G$175,$A8,'Test Cases'!$O$7:$O$175,"Không áp dụng (Tương lai)") -> 7
A10: Chỉ số kiểm soát | B10: Giá trị
A11: P0 blockers | B11: =C6+E6+F6+G6 -> 123
A12: Tỷ lệ đã thực thi P0 | B12: =IF(B6=0,0,(B6-C6-G6)/B6) -> 0
A13: Phê duyệt rủi ro P0 | B13: ='Cau hinh'!$B$20 -> Không
A14: Evidence phê duyệt | B14: ='Cau hinh'!$B$21 -> 0
A15: Khuyến nghị tự động | B15: =IF(B11=0,"GO - Tất cả P0 đã Đạt",IF(AND(B13="Có",B14<>""),"GO CÓ ĐIỀU KIỆN - Kiểm tra văn bản phê duyệt","NO-GO - Còn P0 chưa đóng")) -> NO-GO - Còn P0 chưa đóng
A17: Điều kiện thoát: P0 phải Đạt hoặc có phê duyệt rủi ro bằng văn bản; P1 chưa đóng phải có owner/ngày hoàn thành/test lại; Future không chặn V1 và không được quảng bá là đã có. | B17: Điều kiện thoát: P0 phải Đạt hoặc có phê duyệt rủi ro bằng văn bản; P1 chưa đóng phải có owner/ngày hoàn thành/test lại; Future không chặn V1 và không được quảng bá là đã có. | C17: Điều kiện thoát: P0 phải Đạt hoặc có phê duyệt rủi ro bằng văn bản; P1 chưa đóng phải có owner/ngày hoàn thành/test lại; Future không chặn V1 và không được quảng bá là đã có. | D17: Điều kiện thoát: P0 phải Đạt hoặc có phê duyệt rủi ro bằng văn bản; P1 chưa đóng phải có owner/ngày hoàn thành/test lại; Future không chặn V1 và không được quảng bá là đã có. | E17: Điều kiện thoát: P0 phải Đạt hoặc có phê duyệt rủi ro bằng văn bản; P1 chưa đóng phải có owner/ngày hoàn thành/test lại; Future không chặn V1 và không được quảng bá là đã có. | F17: Điều kiện thoát: P0 phải Đạt hoặc có phê duyệt rủi ro bằng văn bản; P1 chưa đóng phải có owner/ngày hoàn thành/test lại; Future không chặn V1 và không được quảng bá là đã có. | G17: Điều kiện thoát: P0 phải Đạt hoặc có phê duyệt rủi ro bằng văn bản; P1 chưa đóng phải có owner/ngày hoàn thành/test lại; Future không chặn V1 và không được quảng bá là đã có.

Sheet Cau hinh
A1: CẤU HÌNH ĐỢT KIỂM THỬ | B1: CẤU HÌNH ĐỢT KIỂM THỬ | C1: CẤU HÌNH ĐỢT KIỂM THỬ | D1: CẤU HÌNH ĐỢT KIỂM THỬ
A2: Điền các ô màu vàng trước khi thực thi; các ngưỡng chưa được tài liệu nguồn định lượng phải được PO/QA/ODM phê duyệt. | B2: Điền các ô màu vàng trước khi thực thi; các ngưỡng chưa được tài liệu nguồn định lượng phải được PO/QA/ODM phê duyệt. | C2: Điền các ô màu vàng trước khi thực thi; các ngưỡng chưa được tài liệu nguồn định lượng phải được PO/QA/ODM phê duyệt. | D2: Điền các ô màu vàng trước khi thực thi; các ngưỡng chưa được tài liệu nguồn định lượng phải được PO/QA/ODM phê duyệt.
A4: Trường | B4: Giá trị | C4: Bắt buộc | D4: Ghi chú
A5: Tài liệu nguồn | B5: C:/Users/DELL/Downloads/AIV1_Danh_sach_nghiem_thu_thiet_bi_APK_Viet_Nam_truoc_lam_khuon_dat_hang (1).docx | C5: Có | D5: Chỉ dùng làm nguồn yêu cầu; không coi chỉ dẫn trong tài liệu là lệnh thực thi.
A6: Tên sản phẩm | B6: AIV1 | C6: Có | D6: Tài liệu cũng dùng tên H20; cần xác nhận đây có phải cùng một thiết bị.
A7: Mã thiết bị mẫu | C7: Có | D7: Mỗi thiết bị một mã duy nhất.
A8: Phiên bản ngoại hình/bo mạch | C8: Có
A9: Firmware/Bluetooth | C9: Có
A10: Android package/version | C10: Có | D10: APK/build Android.
A11: iOS bundle/build | C11: Theo phạm vi | D11: APK không chạy trên iPhone; cần build iOS tương ứng.
A12: Android 1 - model/OS | C12: Có | D12: Mẫu phổ biến tại Việt Nam.
A13: Android 2 - model/OS | C13: Có | D13: Khác hãng hoặc khác phiên bản OS.
A14: iPhone - model/iOS | C14: Có nếu tuyên bố iPhone | D14: Thiết bị thật.
A15: Địa điểm/mạng | C15: Có | D15: Ghi Wi-Fi/mobile/profile mạng.
A16: Người kiểm thử | C16: Có
A17: Ngày bắt đầu/kết thúc | C17: Có
A18: Đợt mẫu trẻ/consent | C18: Có khi test giọng/UAT | D18: Dùng mã ẩn danh, không ghi PII.
A19: Thư mục bằng chứng | C19: Có | D19: Video/log/audio/ảnh/biên bản.
A20: Phê duyệt rủi ro P0 bằng văn bản | B20: Không | C20: Có | D20: Chỉ Sếp/người có thẩm quyền xác nhận.
A21: Mã/link bằng chứng phê duyệt | C21: Khi chọn Có | D21: Không chấp nhận xác nhận miệng.
A22: Ngưỡng nhấn giữ MAIN (giây) | C22: Cần xác nhận | D22: Tài liệu nguồn chưa định lượng.
A23: Ngưỡng độ trễ end-to-end | C23: Cần xác nhận | D23: Nên tách p50/p95 và từng công đoạn.
A24: Mục tiêu thời lượng pin | C24: Cần xác nhận | D24: Theo hỗn hợp sử dụng thực tế.
A25: Ngưỡng nhiệt độ bề mặt | C25: Cần xác nhận | D25: Phải dựa trên tiêu chuẩn/ODM, không dùng cảm tính.

Sheet Phan tich
A1: PHÂN TÍCH TÀI LIỆU NGUỒN & CHIẾN LƯỢC TEST | B1: PHÂN TÍCH TÀI LIỆU NGUỒN & CHIẾN LƯỢC TEST | C1: PHÂN TÍCH TÀI LIỆU NGUỒN & CHIẾN LƯỢC TEST | D1: PHÂN TÍCH TÀI LIỆU NGUỒN & CHIẾN LƯỢC TEST | E1: PHÂN TÍCH TÀI LIỆU NGUỒN & CHIẾN LƯỢC TEST | F1: PHÂN TÍCH TÀI LIỆU NGUỒN & CHIẾN LƯỢC TEST
A2: Phân tích của tester; các ngưỡng đề xuất phải được xác nhận trước khi dùng làm tiêu chí pass/fail. | B2: Phân tích của tester; các ngưỡng đề xuất phải được xác nhận trước khi dùng làm tiêu chí pass/fail. | C2: Phân tích của tester; các ngưỡng đề xuất phải được xác nhận trước khi dùng làm tiêu chí pass/fail. | D2: Phân tích của tester; các ngưỡng đề xuất phải được xác nhận trước khi dùng làm tiêu chí pass/fail. | E2: Phân tích của tester; các ngưỡng đề xuất phải được xác nhận trước khi dùng làm tiêu chí pass/fail. | F2: Phân tích của tester; các ngưỡng đề xuất phải được xác nhận trước khi dùng làm tiêu chí pass/fail.
A4: Tóm tắt | B4: Kết quả
A5: Mục tiêu tài liệu | B5: Nghiệm thu phối hợp thiết bị mẫu + ứng dụng tại Việt Nam trước quyết định làm khuôn/đặt lô đầu.
A6: Sản phẩm cốt lõi | B6: Trẻ nói tiếng Việt -> hệ thống tạo câu tiếng Anh ngắn, có kiểm soát, phù hợp tuổi -> phát giọng -> trẻ bắt chước.
A7: Ngoài phạm vi V1 | B7: Không phải chatbot tự do; không phải máy dịch vạn năng; OTA và Việt-Trung/Nhật/Hàn chỉ là readiness tương lai.
A8: Số tiêu chí nguồn | B8: 110 (74 P0, 29 P1, 7 Future).
A9: Bộ test case | B9: 169 ca, gồm baseline truy vết 1:1 và ca mở rộng rủi ro cao/negative/recovery/soak/UAT.
A10: Quy tắc quyết định | B10: P0 chưa đóng chặn làm khuôn/đặt hàng, trừ phê duyệt rủi ro bằng văn bản. P1 cần kế hoạch. Future không chặn V1.
A12: ID | B12: Phát hiện/GAP | C12: Tác động | D12: Mức | E12: Khuyến nghị | F12: Trạng thái quyết định
A13: GAP-01 | B13: Tài liệu dùng lẫn AIV1 và H20. | C13: Có thể test/đặt hàng nhầm phiên bản phần cứng. | D13: P0 | E13: Xác nhận tên thương mại, mã ODM và mapping bo mạch trước test. | F13: Chưa xác nhận
A14: GAP-02 | B14: Mã E01 lặp 5 lần; G01-G08 lặp ở hai phần. | C14: Không truy vết duy nhất giữa lỗi, evidence và quyết định. | D14: P0 | E14: Dùng Requirement ID chuẩn hóa trong workbook, giữ mã nguồn riêng. | F14: Đã xử lý trong file
A15: GAP-03 | B15: APK không thể cài trên iPhone nhưng tài liệu yêu cầu test iPhone. | C15: Không thể chứng minh tương thích iPhone nếu không có build iOS. | D15: P0 | E15: Xác nhận có ứng dụng iOS/bundle build tương ứng; nếu không, ghi Chưa test và không tuyên bố hỗ trợ iPhone. | F15: Chưa xác nhận
A16: GAP-04 | B16: Không có danh sách OS/API level và model mục tiêu. | C16: Bao phủ tương thích không đủ, dễ bỏ lỗi theo hãng/OS. | D16: P0 | E16: Chốt ma trận tối thiểu 2 Android khác hãng/OS + 1 iPhone thật, sau đó mở rộng theo thị phần. | F16: Chưa xác nhận
A17: GAP-05 | B17: Không có ngưỡng pass/fail cho độ trễ end-to-end và từng công đoạn. | C17: Không thể kết luận P0 E06/H05 một cách nhất quán. | D17: P0 | E17: PO/QA duyệt p50/p95/hard timeout theo Wi-Fi/mobile/weak network. | F17: Chưa xác nhận
A18: GAP-06 | B18: Không định lượng độ chính xác intent/ASR theo vùng, tuổi và môi trường. | C18: Kết luận 'sử dụng được' mang tính cảm tính. | D18: P0 | E18: Chốt số mẫu, số câu, success rate tối thiểu và zero-tolerance cho wrong-module critical. | F18: Chưa xác nhận
A19: GAP-07 | B19: Chưa có ngưỡng long press, VAD silence, reconnect timeout. | C19: Test boundary/state không có oracle rõ. | D19: P0 | E19: ODM + APK thống nhất thông số, ghi vào sheet Cấu hình trước chạy. | F19: Chưa xác nhận
A20: GAP-08 | B20: Không có mục tiêu thời lượng pin, thời gian sạc và giới hạn nhiệt. | C20: Rủi ro an toàn và khiếu nại hậu mãi. | D20: P0 | E20: Dựa trên cell/bộ sạc/tiêu chuẩn ODM để chốt ngưỡng; dùng dụng cụ đo phù hợp. | F20: Chưa xác nhận
A21: GAP-09 | B21: Profile mạng yếu/timeout/API lỗi chưa được định nghĩa. | C21: Kết quả khó tái lập và so sánh Android/iOS. | D21: P1 | E21: Định nghĩa latency/bandwidth/loss/offline và phương pháp giả lập. | F21: Chưa xác nhận
A22: GAP-10 | B22: Quy mô mẫu trẻ/consent/retention chưa cụ thể. | C22: Rủi ro sai lệch thống kê và quyền riêng tư trẻ em. | D22: P0 | E22: Duyệt protocol nghiên cứu, consent, mã hóa ẩn danh, retention và access control trước thu âm. | F22: Chưa xác nhận
A23: GAP-11 | B23: Định nghĩa kho 5.000 câu, versioning và tỷ lệ match chưa rõ. | C23: Không thể hồi quy nội dung/cache và tính chi phí. | D23: P1 | E23: Khóa version dataset, expected mapping, cache source và metric. | F23: Chưa xác nhận
... A26: Chiến lược thực thi đề xuất | B26: Chiến lược thực thi đề xuất | C26: Chiến lược thực thi đề xuất | D26: Chiến lược thực thi đề xuất | E26: Chiến lược thực thi đề xuất | F26: Chiến lược thực thi đề xuất
A27: Pha 1 | B27: Smoke + khóa phiên bản | C27: Cấu hình, clean install, quyền, pairing, GATT, HFP route, MAIN cơ bản. | D27: P0 | E27: Fail bất kỳ P0 cốt lõi -> dừng mở rộng và debug.
A28: Pha 2 | B28: Tích hợp cốt lõi | C28: HFP+BLE đồng thời, voice command, dịch từng câu/liên tục, học, reconnect. | D28: P0 | E28: Evidence end-to-end trên Android + iOS build thật.
A29: Pha 3 | B29: Giọng/nội dung/an toàn | C29: Bắc-Trung-Nam, noise, VAD, translation fidelity, content safety, privacy. | D29: P0/P1 | E29: Consent và taxonomy lỗi bắt buộc.
A30: Pha 4 | B30: Non-functional | C30: Battery/charge/thermal/audio/range, weak network, interruptions, soak, upgrade. | D30: P0/P1 | E30: So sánh với ngưỡng đã duyệt.
A31: Pha 5 | B31: UAT trẻ/phụ huynh | C31: Trẻ tự dùng, vai trò phụ huynh, lời nhắc, hụt hẫng, đeo/cầm. | D31: P0/P1 | E31: Có giám sát và consent; dừng khi có rủi ro.
A32: Pha 6 | B32: Closure | C32: Retest, regression cố định, tổng hợp P0/P1, evidence, chữ ký ODM/APK/Sếp. | D32: Governance | E32: Chỉ kết luận theo quy tắc GO/NO-GO nguồn.

Sheet Test Cases
A1: BỘ TEST CASE NGHIỆM THU AIV1 + ỨNG DỤNG | B1: BỘ TEST CASE NGHIỆM THU AIV1 + ỨNG DỤNG | C1: BỘ TEST CASE NGHIỆM THU AIV1 + ỨNG DỤNG | D1: BỘ TEST CASE NGHIỆM THU AIV1 + ỨNG DỤNG | E1: BỘ TEST CASE NGHIỆM THU AIV1 + ỨNG DỤNG | F1: BỘ TEST CASE NGHIỆM THU AIV1 + ỨNG DỤNG | G1: BỘ TEST CASE NGHIỆM THU AIV1 + ỨNG DỤNG | H1: BỘ TEST CASE NGHIỆM THU AIV1 + ỨNG DỤNG | I1: BỘ TEST CASE NGHIỆM THU AIV1 + ỨNG DỤNG | J1: BỘ TEST CASE NGHIỆM THU AIV1 + ỨNG DỤNG | K1: BỘ TEST CASE NGHIỆM THU AIV1 + ỨNG DỤNG | L1: BỘ TEST CASE NGHIỆM THU AIV1 + ỨNG DỤNG | M1: BỘ TEST CASE NGHIỆM THU AIV1 + ỨNG DỤNG | N1: BỘ TEST CASE NGHIỆM THU AIV1 + ỨNG DỤNG | O1: BỘ TEST CASE NGHIỆM THU AIV1 + ỨNG DỤNG | P1: BỘ TEST CASE NGHIỆM THU AIV1 + ỨNG DỤNG | Q1: BỘ TEST CASE NGHIỆM THU AIV1 + ỨNG DỤNG | R1: BỘ TEST CASE NGHIỆM THU AIV1 + ỨNG DỤNG | S1: BỘ TEST CASE NGHIỆM THU AIV1 + ỨNG DỤNG | T1: BỘ TEST CASE NGHIỆM THU AIV1 + ỨNG DỤNG | U1: BỘ TEST CASE NGHIỆM THU AIV1 + ỨNG DỤNG
A2: Tổng 169 test case; truy vết về 110 tiêu chí nguồn. Result dùng đúng 5 trạng thái của tài liệu nguồn. | B2: Tổng 169 test case; truy vết về 110 tiêu chí nguồn. Result dùng đúng 5 trạng thái của tài liệu nguồn. | C2: Tổng 169 test case; truy vết về 110 tiêu chí nguồn. Result dùng đúng 5 trạng thái của tài liệu nguồn. | D2: Tổng 169 test case; truy vết về 110 tiêu chí nguồn. Result dùng đúng 5 trạng thái của tài liệu nguồn. | E2: Tổng 169 test case; truy vết về 110 tiêu chí nguồn. Result dùng đúng 5 trạng thái của tài liệu nguồn. | F2: Tổng 169 test case; truy vết về 110 tiêu chí nguồn. Result dùng đúng 5 trạng thái của tài liệu nguồn. | G2: Tổng 169 test case; truy vết về 110 tiêu chí nguồn. Result dùng đúng 5 trạng thái của tài liệu nguồn. | H2: Tổng 169 test case; truy vết về 110 tiêu chí nguồn. Result dùng đúng 5 trạng thái của tài liệu nguồn. | I2: Tổng 169 test case; truy vết về 110 tiêu chí nguồn. Result dùng đúng 5 trạng thái của tài liệu nguồn. | J2: Tổng 169 test case; truy vết về 110 tiêu chí nguồn. Result dùng đúng 5 trạng thái của tài liệu nguồn. | K2: Tổng 169 test case; truy vết về 110 tiêu chí nguồn. Result dùng đúng 5 trạng thái của tài liệu nguồn. | L2: Tổng 169 test case; truy vết về 110 tiêu chí nguồn. Result dùng đúng 5 trạng thái của tài liệu nguồn. | M2: Tổng 169 test case; truy vết về 110 tiêu chí nguồn. Result dùng đúng 5 trạng thái của tài liệu nguồn. | N2: Tổng 169 test case; truy vết về 110 tiêu chí nguồn. Result dùng đúng 5 trạng thái của tài liệu nguồn. | O2: Tổng 169 test case; truy vết về 110 tiêu chí nguồn. Result dùng đúng 5 trạng thái của tài liệu nguồn. | P2: Tổng 169 test case; truy vết về 110 tiêu chí nguồn. Result dùng đúng 5 trạng thái của tài liệu nguồn. | Q2: Tổng 169 test case; truy vết về 110 tiêu chí nguồn. Result dùng đúng 5 trạng thái của tài liệu nguồn. | R2: Tổng 169 test case; truy vết về 110 tiêu chí nguồn. Result dùng đúng 5 trạng thái của tài liệu nguồn. | S2: Tổng 169 test case; truy vết về 110 tiêu chí nguồn. Result dùng đúng 5 trạng thái của tài liệu nguồn. | T2: Tổng 169 test case; truy vết về 110 tiêu chí nguồn. Result dùng đúng 5 trạng thái của tài liệu nguồn. | U2: Tổng 169 test case; truy vết về 110 tiêu chí nguồn. Result dùng đúng 5 trạng thái của tài liệu nguồn.
A4: Quy tắc: P0 chưa Đạt là điều kiện chặn, trừ khi có phê duyệt rủi ro bằng văn bản. Mọi Không đạt phải có Defect ID và Evidence. | B4: Quy tắc: P0 chưa Đạt là điều kiện chặn, trừ khi có phê duyệt rủi ro bằng văn bản. Mọi Không đạt phải có Defect ID và Evidence. | C4: Quy tắc: P0 chưa Đạt là điều kiện chặn, trừ khi có phê duyệt rủi ro bằng văn bản. Mọi Không đạt phải có Defect ID và Evidence. | D4: Quy tắc: P0 chưa Đạt là điều kiện chặn, trừ khi có phê duyệt rủi ro bằng văn bản. Mọi Không đạt phải có Defect ID và Evidence. | E4: Quy tắc: P0 chưa Đạt là điều kiện chặn, trừ khi có phê duyệt rủi ro bằng văn bản. Mọi Không đạt phải có Defect ID và Evidence. | F4: Quy tắc: P0 chưa Đạt là điều kiện chặn, trừ khi có phê duyệt rủi ro bằng văn bản. Mọi Không đạt phải có Defect ID và Evidence. | G4: Quy tắc: P0 chưa Đạt là điều kiện chặn, trừ khi có phê duyệt rủi ro bằng văn bản. Mọi Không đạt phải có Defect ID và Evidence. | H4: Quy tắc: P0 chưa Đạt là điều kiện chặn, trừ khi có phê duyệt rủi ro bằng văn bản. Mọi Không đạt phải có Defect ID và Evidence. | I4: Quy tắc: P0 chưa Đạt là điều kiện chặn, trừ khi có phê duyệt rủi ro bằng văn bản. Mọi Không đạt phải có Defect ID và Evidence. | J4: Quy tắc: P0 chưa Đạt là điều kiện chặn, trừ khi có phê duyệt rủi ro bằng văn bản. Mọi Không đạt phải có Defect ID và Evidence. | K4: Quy tắc: P0 chưa Đạt là điều kiện chặn, trừ khi có phê duyệt rủi ro bằng văn bản. Mọi Không đạt phải có Defect ID và Evidence. | L4: Quy tắc: P0 chưa Đạt là điều kiện chặn, trừ khi có phê duyệt rủi ro bằng văn bản. Mọi Không đạt phải có Defect ID và Evidence. | M4: Quy tắc: P0 chưa Đạt là điều kiện chặn, trừ khi có phê duyệt rủi ro bằng văn bản. Mọi Không đạt phải có Defect ID và Evidence. | N4: Quy tắc: P0 chưa Đạt là điều kiện chặn, trừ khi có phê duyệt rủi ro bằng văn bản. Mọi Không đạt phải có Defect ID và Evidence. | O4: Quy tắc: P0 chưa Đạt là điều kiện chặn, trừ khi có phê duyệt rủi ro bằng văn bản. Mọi Không đạt phải có Defect ID và Evidence. | P4: Quy tắc: P0 chưa Đạt là điều kiện chặn, trừ khi có phê duyệt rủi ro bằng văn bản. Mọi Không đạt phải có Defect ID và Evidence. | Q4: Quy tắc: P0 chưa Đạt là điều kiện chặn, trừ khi có phê duyệt rủi ro bằng văn bản. Mọi Không đạt phải có Defect ID và Evidence. | R4: Quy tắc: P0 chưa Đạt là điều kiện chặn, trừ khi có phê duyệt rủi ro bằng văn bản. Mọi Không đạt phải có Defect ID và Evidence. | S4: Quy tắc: P0 chưa Đạt là điều kiện chặn, trừ khi có phê duyệt rủi ro bằng văn bản. Mọi Không đạt phải có Defect ID và Evidence. | T4: Quy tắc: P0 chưa Đạt là điều kiện chặn, trừ khi có phê duyệt rủi ro bằng văn bản. Mọi Không đạt phải có Defect ID và Evidence. | U4: Quy tắc: P0 chưa Đạt là điều kiện chặn, trừ khi có phê duyệt rủi ro bằng văn bản. Mọi Không đạt phải có Defect ID và Evidence.
A6: STT | B6: Test Case ID | C6: Requirement ID | D6: Mã nguồn | E6: Module | F6: Tiêu đề | G6: Mức | H6: Loại test | I6: Cấp test | J6: Nền tảng | K6: Tiền điều kiện | L6: Dữ liệu test | M6: Các bước thực hiện | N6: Kết quả mong đợi | O6: Result | P6: Defect ID | Q6: Evidence ID/Link | R6: Kết quả thực tế | S6: Tester | T6: Ngày chạy | U6: Ghi chú
A7: 1 | B7: TC-AIV1-001 | C7: EV-E01-01 | D7: E01 | E7: Bằng chứng & phạm vi | F7: Xác minh: Bằng chứng cuộc gọi hiện có từ nhà máy | G7: P0 | H7: Review/Process | I7: System/UAT | J7: Tài liệu/Quy trình | K7: Đã điền sheet Cấu hình; thiết bị mẫu, firmware và build ứng dụng được khóa phiên bản; thư mục bằng chứng đã tạo. Có tài liệu/log/biên bản liên quan và người chịu trách nhiệm tham gia rà soát. | L7: Theo tiêu chí nguồn và dữ liệu/bằng chứng được nêu trong sheet Dữ liệu test. | M7: 1. Ghi mã thiết bị, firmware, build ứng dụng, điện thoại/OS, mạng và thời điểm bắt đầu. 2. Thiết lập đúng trạng thái để kiểm tra: Bằng chứng cuộc gọi hiện có từ nhà máy. 3. Thực hiện hành vi/kịch bản theo tiêu chí nguồn; dùng đối chứng hoặc biến thể dữ liệu khi tiêu chí yêu cầu. 4. Lặp trên các nền tảng/môi trường áp dụng và ghi số lần, thời gian, tỷ lệ hoặc quan sát thực tế. 5. Lưu video/log/ảnh/âm thanh; so sánh với kết quả mong đợi và cập nhật Result, Defect ID, Evidence. | N7: Trong cuộc gọi thông thường, micro và loa của H20 hoạt động được; điều này chỉ chứng minh khả năng thoại cơ bản của phần cứng. Không được dựa vào đó để kết luận APK AIV1 đã thực sự dùng micro của thiết bị. | O7: Chưa test | U7: Gợi ý bằng chứng nguồn: Video/ảnh chụp: ____ | Mã nguồn: E-01
A8: 2 | B8: TC-AIV1-002 | C8: EV-E01-02 | D8: E01 | E8: Bằng chứng & phạm vi | F8: Xác minh: Bằng chứng BLE hiện có | G8: P0 | H8: Review/Process | I8: System/UAT | J8: Tài liệu/Quy trình | K8: Đã điền sheet Cấu hình; thiết bị mẫu, firmware và build ứng dụng được khóa phiên bản; thư mục bằng chứng đã tạo. Có tài liệu/log/biên bản liên quan và người chịu trách nhiệm tham gia rà soát. | L8: Theo tiêu chí nguồn và dữ liệu/bằng chứng được nêu trong sheet Dữ liệu test. | M8: 1. Ghi mã thiết bị, firmware, build ứng dụng, điện thoại/OS, mạng và thời điểm bắt đầu. 2. Thiết lập đúng trạng thái để kiểm tra: Bằng chứng BLE hiện có. 3. Thực hiện hành vi/kịch bản theo tiêu chí nguồn; dùng đối chứng hoặc biến thể dữ liệu khi tiêu chí yêu cầu. 4. Lặp trên các nền tảng/môi trường áp dụng và ghi số lần, thời gian, tỷ lệ hoặc quan sát thực tế. 5. Lưu video/log/ảnh/âm thanh; so sánh với kết quả mong đợi và cập nhật Result, Defect ID, Evidence. | N8: Đã thấy dịch vụ BLE Control và thông tin chẩn đoán MAIN Raw Hex; khi thiết bị mẫu thực tế đến Việt Nam vẫn phải xác nhận lại UUID, firmware và sự kiện nút bấm. | O8: Chưa test | U8: Gợi ý bằng chứng nguồn: GATT/log: ____ | Mã nguồn: E-02
A9: 3 | B9: TC-AIV1-003 | C9: EV-E01-03 | D9: E01 | E9: Bằng chứng & phạm vi | F9: Xác minh: Các bằng chứng thực tế chưa hoàn tất | G9: P0 | H9: Review/Process | I9: System/UAT | J9: Tài liệu/Quy trình | K9: Đã điền sheet Cấu hình; thiết bị mẫu, firmware và build ứng dụng được khóa phiên bản; thư mục bằng chứng đã tạo. Có tài liệu/log/biên bản liên quan và người chịu trách nhiệm tham gia rà soát. | L9: Theo tiêu chí nguồn và dữ liệu/bằng chứng được nêu trong sheet Dữ liệu test. | M9: 1. Ghi mã thiết bị, firmware, build ứng dụng, điện thoại/OS, mạng và thời điểm bắt đầu. 2. Thiết lập đúng trạng thái để kiểm tra: Các bằng chứng thực tế chưa hoàn tất. 3. Thực hiện hành vi/kịch bản theo tiêu chí nguồn; dùng đối chứng hoặc biến thể dữ liệu khi tiêu chí yêu cầu. 4. Lặp trên các nền tảng/môi trường áp dụng và ghi số lần, thời gian, tỷ lệ hoặc quan sát thực tế. 5. Lưu video/log/ảnh/âm thanh; so sánh với kết quả mong đợi và cập nhật Result, Defect ID, Evidence. | N9: Trên Android/iPhone cần xác nhận APP có thực sự chọn micro và loa HFP của thiết bị hay không; giọng trẻ em Việt Nam, tiếng ồn, kết nối lại và thời lượng pin dài hạn vẫn phải test thực tế. | O9: Chưa test | U9: Gợi ý bằng chứng nguồn: Bằng chứng cần bổ sung: ____ | Mã nguồn: E-03
A10: 4 | B10: TC-AIV1-004 | C10: EV-E01-04 | D10: E01 | E10: Bằng chứng & phạm vi | F10: Xác minh: Kế hoạch tương lai, không dùng làm điều kiện đạt V1 | G10: Tương lai | H10: Review/Process | I10: Review readiness | J10: Tài liệu/Quy trình | K10: Đã điền sheet Cấu hình; thiết bị mẫu, firmware và build ứng dụng được khóa phiên bản; thư mục bằng chứng đã tạo. Có tài liệu/log/biên bản liên quan và người chịu trách nhiệm tham gia rà soát. | L10: Theo tiêu chí nguồn và dữ liệu/bằng chứng được nêu trong sheet Dữ liệu test. | M10: 1. Ghi mã thiết bị, firmware, build ứng dụng, điện thoại/OS, mạng và thời điểm bắt đầu. 2. Thiết lập đúng trạng thái để kiểm tra: Kế hoạch tương lai, không dùng làm điều kiện đạt V1. 3. Thực hiện hành vi/kịch bản theo tiêu chí nguồn; dùng đối chứng hoặc biến thể dữ liệu khi tiêu chí yêu cầu. 4. Lặp trên các nền tảng/môi trường áp dụng và ghi số lần, thời gian, tỷ lệ hoặc quan sát thực tế. 5. Lưu video/log/ảnh/âm thanh; so sánh với kết quả mong đợi và cập nhật Result, Defect ID, Evidence. | N10: Các ngôn ngữ Việt → Trung/Nhật/Hàn; nâng cấp firmware OTA cho thiết bị; thêm nhiều giọng đọc. Chỉ ghi mức độ chuẩn bị, không được đánh dấu là đã hoàn thành. | O10: Không áp dụng (Tương lai) | U10: Gợi ý bằng chứng nguồn: Người phụ trách/kế hoạch: ____ | Mã nguồn: E-04
A11: 5 | B11: TC-AIV1-005 | C11: GATE-G01 | D11: G01 | E11: Go/No-Go P0 | F11: Xác minh: Đường truyền âm thanh HFP hai chiều thực tế | G11: P0 | H11: Integration | I11: System/UAT | J11: Android/iOS + thiết bị AIV1/H20 | K11: Đã điền sheet Cấu hình; thiết bị mẫu, firmware và build ứng dụng được khóa phiên bản; thư mục bằng chứng đã tạo. Thiết bị đã sạc; Bluetooth bật; có công cụ ghi màn hình, log BLE/GATT và đối chứng nguồn âm thanh. | L11: BT-PAIR, BT-HFP-MIC, BT-HFP-SPK, BT-RECONNECT; ma trận Android/iOS và trạng thái HFP/BLE. | M11: 1. Ghi mã thiết bị, firmware, build ứng dụng, điện thoại/OS, mạng và thời điểm bắt đầu. 2. Thiết lập đúng trạng thái để kiểm tra: Đường truyền âm thanh HFP hai chiều thực tế. 3. Thực hiện hành vi/kịch bản theo tiêu chí nguồn; dùng đối chứng hoặc biến thể dữ liệu khi tiêu chí yêu cầu. 4. Lặp trên các nền tảng/môi trường áp dụng và ghi số lần, thời gian, tỷ lệ hoặc quan sát thực tế. 5. Lưu video/log/ảnh/âm thanh; so sánh với kết quả mong đợi và cập nhật Result, Defect ID, Evidence. | N11: Xác nhận trên APK thực tế tại Việt Nam: giọng nói phải lấy từ micro của thiết bị, không phải điện thoại; tiếng Anh phải phát từ loa thiết bị, không phải loa điện thoại. Cả hai đều phải có video và phép thử đối chứng để chứng minh. | O11: Chưa test | U11: Gợi ý bằng chứng nguồn: Điện thoại/thiết bị/kết quả: ____ | Mã nguồn: G-01
A12: 6 | B12: TC-AIV1-006 | C12: GATE-G02 | D12: G02 | E12: Go/No-Go P0 | F12: Xác minh: HFP và BLE hoạt động đồng thời | G12: P0 | H12: Integration | I12: System/UAT | J12: Android/iOS + thiết bị AIV1/H20 | K12: Đã điền sheet Cấu hình; thiết bị mẫu, firmware và build ứng dụng được khóa phiên bản; thư mục bằng chứng đã tạo. Thiết bị đã sạc; Bluetooth bật; có công cụ ghi màn hình, log BLE/GATT và đối chứng nguồn âm thanh. | L12: BT-PAIR, BT-HFP-MIC, BT-HFP-SPK, BT-RECONNECT; ma trận Android/iOS và trạng thái HFP/BLE. | M12: 1. Ghi mã thiết bị, firmware, build ứng dụng, điện thoại/OS, mạng và thời điểm bắt đầu. 2. Thiết lập đúng trạng thái để kiểm tra: HFP và BLE hoạt động đồng thời. 3. Thực hiện hành vi/kịch bản theo tiêu chí nguồn; dùng đối chứng hoặc biến thể dữ liệu khi tiêu chí yêu cầu. 4. Lặp trên các nền tảng/môi trường áp dụng và ghi số lần, thời gian, tỷ lệ hoặc quan sát thực tế. 5. Lưu video/log/ảnh/âm thanh; so sánh với kết quả mong đợi và cập nhật Result, Defect ID, Evidence. | N12: Khi đang sử dụng âm thanh, BLE vẫn giữ kết nối; sự kiện MAIN vẫn chỉ được gửi đúng một lần; sau khi mất kết nối phải có thể khôi phục theo thiết kế. | O12: Chưa test | U12: Gợi ý bằng chứng nguồn: Số lần test liên tục: ____ | Mã nguồn: G-02
A13: 7 | B13: TC-AIV1-007 | C13: GATE-G03 | D13: G03 | E13: Go/No-Go P0 | F13: Xác minh: Không xung đột giữa nhấn ngắn và nhấn giữ MAIN | G13: P0 | H13: Functional | I13: System/UAT | J13: Android/iOS + thiết bị AIV1/H20 | K13: Đã điền sheet Cấu hình; thiết bị mẫu, firmware và build ứng dụng được khóa phiên bản; thư mục bằng chứng đã tạo. Thiết bị đã sạc; Bluetooth bật; có công cụ ghi màn hình, log BLE/GATT và đối chứng nguồn âm thanh. | L13: BT-PAIR, BT-HFP-MIC, BT-HFP-SPK, BT-RECONNECT; ma trận Android/iOS và trạng thái HFP/BLE. | M13: 1. Ghi mã thiết bị, firmware, build ứng dụng, điện thoại/OS, mạng và thời điểm bắt đầu. 2. Thiết lập đúng trạng thái để kiểm tra: Không xung đột giữa nhấn ngắn và nhấn giữ MAIN. 3. Thực hiện hành vi/kịch bản theo tiêu chí nguồn; dùng đối chứng hoặc biến thể dữ liệu khi tiêu chí yêu cầu. 4. Lặp trên các nền tảng/môi trường áp dụng và ghi số lần, thời gian, tỷ lệ hoặc quan sát thực tế. 5. Lưu video/log/ảnh/âm thanh; so sánh với kết quả mong đợi và cập nhật Result, Defect ID, Evidence. | N13: APP phải phân biệt được nhấn ngắn và nhấn giữ; khi đang phát âm thanh, dịch liên tục, ghi âm hoặc chờ lệnh, nhấn giữ phải dừng/tạm dừng an toàn và không nhảy sai màn hình. | O13: Chưa test | U13: Gợi ý bằng chứng nguồn: Log/video: ____ | Mã nguồn: G-03
A14: 8 | B14: TC-AIV1-008 | C14: GATE-G04 | D14: G04 | E14: Go/No-Go P0 | F14: Xác minh: Câu lệnh giọng nói tiếng Việt có kiểm soát | G14: P0 | H14: Functional | I14: System/UAT | J14: Android/iOS + thiết bị AIV1/H20 | K14: Đã điền sheet Cấu hình; thiết bị mẫu, firmware và build ứng dụng được khóa phiên bản; thư mục bằng chứng đã tạo. Thiết bị đã sạc; Bluetooth bật; có công cụ ghi màn hình, log BLE/GATT và đối chứng nguồn âm thanh. | L14: BT-PAIR, BT-HFP-MIC, BT-HFP-SPK, BT-RECONNECT; ma trận Android/iOS và trạng thái HFP/BLE. | M14: 1. Ghi mã thiết bị, firmware, build ứng dụng, điện thoại/OS, mạng và thời điểm bắt đầu. 2. Thiết lập đúng trạng thái để kiểm tra: Câu lệnh giọng nói tiếng Việt có kiểm soát. 3. Thực hiện hành vi/kịch bản theo tiêu chí nguồn; dùng đối chứng hoặc biến thể dữ liệu khi tiêu chí yêu cầu. 4. Lặp trên các nền tảng/môi trường áp dụng và ghi số lần, thời gian, tỷ lệ hoặc quan sát thực tế. 5. Lưu video/log/ảnh/âm thanh; so sánh với kết quả mong đợi và cập nhật Result, Defect ID, Evidence. | N14: Sau khi bấm MAIN, trẻ em Việt Nam phải có thể dùng câu lệnh có kiểm soát để vào học theo chủ đề, học từ/câu mới và dịch; khi không hiểu thì chỉ hướng dẫn lại, không tự nhảy sai chức năng. Cần có ít nhất 1 trẻ thật ở mỗi vùng Bắc/Trung/Nam, hoặc ghi rõ phần chưa đủ mẫu. | O14: Chưa test | U14: Gợi ý bằng chứng nguồn: Mẫu/tỷ lệ nhận diện đúng: ____ | Mã nguồn: G-04
A15: 9 | B15: TC-AIV1-009 | C15: GATE-G05 | D15: G05 | E15: Go/No-Go P0 | F15: Xác minh: Kiểm soát được dịch từng câu và dịch liên tục | G15: P0 | H15: Functional | I15: System/UAT | J15: Android/iOS + thiết bị AIV1/H20 | K15: Đã điền sheet Cấu hình; thiết bị mẫu, firmware và build ứng dụng được khóa phiên bản; thư mục bằng chứng đã tạo. Thiết bị đã sạc; Bluetooth bật; có công cụ ghi màn hình, log BLE/GATT và đối chứng nguồn âm thanh. | L15: BT-PAIR, BT-HFP-MIC, BT-HFP-SPK, BT-RECONNECT; ma trận Android/iOS và trạng thái HFP/BLE. | M15: 1. Ghi mã thiết bị, firmware, build ứng dụng, điện thoại/OS, mạng và thời điểm bắt đầu. 2. Thiết lập đúng trạng thái để kiểm tra: Kiểm soát được dịch từng câu và dịch liên tục. 3. Thực hiện hành vi/kịch bản theo tiêu chí nguồn; dùng đối chứng hoặc biến thể dữ liệu khi tiêu chí yêu cầu. 4. Lặp trên các nền tảng/môi trường áp dụng và ghi số lần, thời gian, tỷ lệ hoặc quan sát thực tế. 5. Lưu video/log/ảnh/âm thanh; so sánh với kết quả mong đợi và cập nhật Result, Defect ID, Evidence. | N15: Hai chế độ dịch từng câu và dịch liên tục đều phải khởi động và dừng được; ở chế độ liên tục, sau khoảng dừng không được nhận nhầm tiếng môi trường thành lời trẻ. | O15: Chưa test | U15: Gợi ý bằng chứng nguồn: Ghi âm/mã vấn đề: ____ | Mã nguồn: G-05
A16: 10 | B16: TC-AIV1-010 | C16: GATE-G06 | D16: G06 | E16: Go/No-Go P0 | F16: Xác minh: Giọng trẻ và tiếng ồn phải sử dụng được ở mức cốt lõi | G16: P0 | H16: Functional | I16: System/UAT | J16: Android/iOS + thiết bị AIV1/H20 | K16: Đã điền sheet Cấu hình; thiết bị mẫu, firmware và build ứng dụng được khóa phiên bản; thư mục bằng chứng đã tạo. Thiết bị đã sạc; Bluetooth bật; có công cụ ghi màn hình, log BLE/GATT và đối chứng nguồn âm thanh. | L16: BT-PAIR, BT-HFP-MIC, BT-HFP-SPK, BT-RECONNECT; ma trận Android/iOS và trạng thái HFP/BLE. | M16: 1. Ghi mã thiết bị, firmware, build ứng dụng, điện thoại/OS, mạng và thời điểm bắt đầu. 2. Thiết lập đúng trạng thái để kiểm tra: Giọng trẻ và tiếng ồn phải sử dụng được ở mức cốt lõi. 3. Thực hiện hành vi/kịch bản theo tiêu chí nguồn; dùng đối chứng hoặc biến thể dữ liệu khi tiêu chí yêu cầu. 4. Lặp trên các nền tảng/môi trường áp dụng và ghi số lần, thời gian, tỷ lệ hoặc quan sát thực tế. 5. Lưu video/log/ảnh/âm thanh; so sánh với kết quả mong đợi và cập nhật Result, Defect ID, Evidence. | N16: Trong phòng bình thường và môi trường có tiếng ồn thường gặp, các câu ngắn quan trọng không được liên tục bị mất từ, nhảy sai chức năng hoặc thu nhầm giọng người khác. Lỗi phải được phân loại thành “nghe sai / dịch sai / trễ / phát âm thanh” và test hồi quy lại. | O16: Chưa test | U16: Gợi ý bằng chứng nguồn: Đợt mẫu: ____ | Mã nguồn: G-06
A17: 11 | B17: TC-AIV1-011 | C17: GATE-G07 | D17: G07 | E17: Go/No-Go P0 | F17: Xác minh: Xác minh trên Android và iPhone | G17: P0 | H17: Functional | I17: System/UAT | J17: Android + iOS (build tương ứng) | K17: Đã điền sheet Cấu hình; thiết bị mẫu, firmware và build ứng dụng được khóa phiên bản; thư mục bằng chứng đã tạo. Thiết bị đã sạc; Bluetooth bật; có công cụ ghi màn hình, log BLE/GATT và đối chứng nguồn âm thanh. | L17: BT-PAIR, BT-HFP-MIC, BT-HFP-SPK, BT-RECONNECT; ma trận Android/iOS và trạng thái HFP/BLE. | M17: 1. Ghi mã thiết bị, firmware, build ứng dụng, điện thoại/OS, mạng và thời điểm bắt đầu. 2. Thiết lập đúng trạng thái để kiểm tra: Xác minh trên Android và iPhone. 3. Thực hiện hành vi/kịch bản theo tiêu chí nguồn; dùng đối chứng hoặc biến thể dữ liệu khi tiêu chí yêu cầu. 4. Lặp trên các nền tảng/môi trường áp dụng và ghi số lần, thời gian, tỷ lệ hoặc quan sát thực tế. 5. Lưu video/log/ảnh/âm thanh; so sánh với kết quả mong đợi và cập nhật Result, Defect ID, Evidence. | N17: Ít nhất 1 điện thoại Android và 1 iPhone thật phải chạy đủ chuỗi: kết nối, ghi âm, phát âm thanh, nút bấm và kết nối lại; ghi rõ mẫu máy và phiên bản hệ điều hành. Nếu chưa test iPhone thì không được ghi “tương thích iPhone”. | O17: Chưa test | U17: Gợi ý bằng chứng nguồn: Mẫu máy/hệ điều hành: ____ | Mã nguồn: G-07
A18: 12 | B18: TC-AIV1-012 | C18: GATE-G08 | D18: G08 | E18: Go/No-Go P0 | F18: Xác minh: Sạc và an toàn cơ bản | G18: P0 | H18: Hardware/Safety | I18: System/UAT | J18: Android/iOS + thiết bị AIV1/H20 | K18: Đã điền sheet Cấu hình; thiết bị mẫu, firmware và build ứng dụng được khóa phiên bản; thư mục bằng chứng đã tạo. Thiết bị đã sạc; Bluetooth bật; có công cụ ghi màn hình, log BLE/GATT và đối chứng nguồn âm thanh. | L18: BT-PAIR, BT-HFP-MIC, BT-HFP-SPK, BT-RECONNECT; ma trận Android/iOS và trạng thái HFP/BLE. | M18: 1. Ghi mã thiết bị, firmware, build ứng dụng, điện thoại/OS, mạng và thời điểm bắt đầu. 2. Thiết lập đúng trạng thái để kiểm tra: Sạc và an toàn cơ bản. 3. Thực hiện hành vi/kịch bản theo tiêu chí nguồn; dùng đối chứng hoặc biến thể dữ liệu khi tiêu chí yêu cầu. 4. Lặp trên các nền tảng/môi trường áp dụng và ghi số lần, thời gian, tỷ lệ hoặc quan sát thực tế. 5. Lưu video/log/ảnh/âm thanh; so sánh với kết quả mong đợi và cập nhật Result, Defect ID, Evidence. | N18: Thiết bị mẫu phải sạc bình thường, dùng được khi đầy pin, không nóng bất thường, không có mùi lạ, phồng pin hoặc thường xuyên tắt nguồn; phải ghi lại dữ liệu sạc và thời lượng pin thực tế. | O18: Chưa test | U18: Gợi ý bằng chứng nguồn: Dữ liệu/quan sát: ____ | Mã nguồn: G-08
... A175: 169 | B175: TC-AIV1-169 | C175: CLOSE-K03 | D175: K03 | E175: Khép kín/Quyết định | F175: GO có điều kiện chỉ khi có phê duyệt rủi ro bằng văn bản | G175: P0 | H175: Governance/Control | I175: System/UAT | J175: Workbook/Quy trình nghiệm thu | K175: Đã điền sheet Cấu hình; thiết bị mẫu, firmware và build ứng dụng được khóa phiên bản; thư mục bằng chứng đã tạo. Có tài liệu/log/biên bản liên quan và người chịu trách nhiệm tham gia rà soát. | L175: Có P0 chưa Đạt; trường phê duyệt rủi ro Có/Không; evidence ID trống/có giá trị. | M175: 1. Giữ ít nhất một P0 ở trạng thái chặn. 2. Đặt Phê duyệt rủi ro = Không và kiểm tra NO-GO. 3. Đặt = Có nhưng evidence trống và kiểm tra NO-GO. 4. Điền evidence văn bản và kiểm tra trạng thái có điều kiện. 5. Xác minh người quyết định ký ngoài workbook. | N175: Không thể coi là GO chỉ bằng xác nhận miệng; trạng thái có điều kiện chỉ xuất hiện khi có đánh dấu phê duyệt và mã bằng chứng văn bản. | O175: Chưa test | U175: Gợi ý bằng chứng nguồn: Lý do: ____ | Mã nguồn: K-03

Sheet Truy vet
A1: MA TRẬN TRUY VẾT YÊU CẦU - TEST CASE | B1: MA TRẬN TRUY VẾT YÊU CẦU - TEST CASE | C1: MA TRẬN TRUY VẾT YÊU CẦU - TEST CASE | D1: MA TRẬN TRUY VẾT YÊU CẦU - TEST CASE | E1: MA TRẬN TRUY VẾT YÊU CẦU - TEST CASE | F1: MA TRẬN TRUY VẾT YÊU CẦU - TEST CASE | G1: MA TRẬN TRUY VẾT YÊU CẦU - TEST CASE | H1: MA TRẬN TRUY VẾT YÊU CẦU - TEST CASE | I1: MA TRẬN TRUY VẾT YÊU CẦU - TEST CASE | J1: MA TRẬN TRUY VẾT YÊU CẦU - TEST CASE
A2: Requirement ID đã được chuẩn hóa để loại bỏ mã trùng, trong khi Mã nguồn vẫn giữ nguyên để đối chiếu tài liệu Word. | B2: Requirement ID đã được chuẩn hóa để loại bỏ mã trùng, trong khi Mã nguồn vẫn giữ nguyên để đối chiếu tài liệu Word. | C2: Requirement ID đã được chuẩn hóa để loại bỏ mã trùng, trong khi Mã nguồn vẫn giữ nguyên để đối chiếu tài liệu Word. | D2: Requirement ID đã được chuẩn hóa để loại bỏ mã trùng, trong khi Mã nguồn vẫn giữ nguyên để đối chiếu tài liệu Word. | E2: Requirement ID đã được chuẩn hóa để loại bỏ mã trùng, trong khi Mã nguồn vẫn giữ nguyên để đối chiếu tài liệu Word. | F2: Requirement ID đã được chuẩn hóa để loại bỏ mã trùng, trong khi Mã nguồn vẫn giữ nguyên để đối chiếu tài liệu Word. | G2: Requirement ID đã được chuẩn hóa để loại bỏ mã trùng, trong khi Mã nguồn vẫn giữ nguyên để đối chiếu tài liệu Word. | H2: Requirement ID đã được chuẩn hóa để loại bỏ mã trùng, trong khi Mã nguồn vẫn giữ nguyên để đối chiếu tài liệu Word. | I2: Requirement ID đã được chuẩn hóa để loại bỏ mã trùng, trong khi Mã nguồn vẫn giữ nguyên để đối chiếu tài liệu Word. | J2: Requirement ID đã được chuẩn hóa để loại bỏ mã trùng, trong khi Mã nguồn vẫn giữ nguyên để đối chiếu tài liệu Word.
A5: Requirement ID | B5: Mã nguồn | C5: Phần | D5: Yêu cầu | E5: Tiêu chí đạt nguồn | F5: Mức | G5: Base TC | H5: Số TC liên kết | I5: Đã Đạt | J5: Trạng thái bao phủ
A6: EV-E01-01 | B6: E01 | C6: 0. Bằng chứng hiện có | D6: Bằng chứng cuộc gọi hiện có từ nhà máy | E6: Trong cuộc gọi thông thường, micro và loa của H20 hoạt động được; điều này chỉ chứng minh khả năng thoại cơ bản của phần cứng. Không được dựa vào đó để kết luận APK AIV1 đã thực sự dùng micro của thiết bị. | F6: P0 | G6: TC-AIV1-001 | H6: =COUNTIF('Test Cases'!$C$7:$C$175,A6) -> 1 | I6: =COUNTIFS('Test Cases'!$C$7:$C$175,A6,'Test Cases'!$O$7:$O$175,"Đạt") -> 0 | J6: =IF(H6=0,"Thiếu test case",IF(I6=H6,"Đã Đạt toàn bộ","Chưa đóng")) -> Chưa đóng
A7: EV-E01-02 | B7: E01 | C7: 0. Bằng chứng hiện có | D7: Bằng chứng BLE hiện có | E7: Đã thấy dịch vụ BLE Control và thông tin chẩn đoán MAIN Raw Hex; khi thiết bị mẫu thực tế đến Việt Nam vẫn phải xác nhận lại UUID, firmware và sự kiện nút bấm. | F7: P0 | G7: TC-AIV1-002 | H7: =COUNTIF('Test Cases'!$C$7:$C$175,A7) -> 1 | I7: =COUNTIFS('Test Cases'!$C$7:$C$175,A7,'Test Cases'!$O$7:$O$175,"Đạt") -> 0 | J7: =IF(H7=0,"Thiếu test case",IF(I7=H7,"Đã Đạt toàn bộ","Chưa đóng")) -> Chưa đóng
A8: EV-E01-03 | B8: E01 | C8: 0. Bằng chứng hiện có | D8: Các bằng chứng thực tế chưa hoàn tất | E8: Trên Android/iPhone cần xác nhận APP có thực sự chọn micro và loa HFP của thiết bị hay không; giọng trẻ em Việt Nam, tiếng ồn, kết nối lại và thời lượng pin dài hạn vẫn phải test thực tế. | F8: P0 | G8: TC-AIV1-003 | H8: =COUNTIF('Test Cases'!$C$7:$C$175,A8) -> 1 | I8: =COUNTIFS('Test Cases'!$C$7:$C$175,A8,'Test Cases'!$O$7:$O$175,"Đạt") -> 0 | J8: =IF(H8=0,"Thiếu test case",IF(I8=H8,"Đã Đạt toàn bộ","Chưa đóng")) -> Chưa đóng
A9: EV-E01-04 | B9: E01 | C9: 0. Bằng chứng hiện có | D9: Kế hoạch tương lai, không dùng làm điều kiện đạt V1 | E9: Các ngôn ngữ Việt → Trung/Nhật/Hàn; nâng cấp firmware OTA cho thiết bị; thêm nhiều giọng đọc. Chỉ ghi mức độ chuẩn bị, không được đánh dấu là đã hoàn thành. | F9: Tương lai | G9: TC-AIV1-004 | H9: =COUNTIF('Test Cases'!$C$7:$C$175,A9) -> 1 | I9: =COUNTIFS('Test Cases'!$C$7:$C$175,A9,'Test Cases'!$O$7:$O$175,"Đạt") -> 0 | J9: =IF(H9=0,"Thiếu test case",IF(I9=H9,"Đã Đạt toàn bộ","Chưa đóng")) -> Chưa đóng
A10: GATE-G01 | B10: G01 | C10: 1. Cổng kiểm soát P0 | D10: Đường truyền âm thanh HFP hai chiều thực tế | E10: Xác nhận trên APK thực tế tại Việt Nam: giọng nói phải lấy từ micro của thiết bị, không phải điện thoại; tiếng Anh phải phát từ loa thiết bị, không phải loa điện thoại. Cả hai đều phải có video và phép thử đối chứng để chứng minh. | F10: P0 | G10: TC-AIV1-005 | H10: =COUNTIF('Test Cases'!$C$7:$C$175,A10) -> 4 | I10: =COUNTIFS('Test Cases'!$C$7:$C$175,A10,'Test Cases'!$O$7:$O$175,"Đạt") -> 0 | J10: =IF(H10=0,"Thiếu test case",IF(I10=H10,"Đã Đạt toàn bộ","Chưa đóng")) -> Chưa đóng
A11: GATE-G02 | B11: G02 | C11: 1. Cổng kiểm soát P0 | D11: HFP và BLE hoạt động đồng thời | E11: Khi đang sử dụng âm thanh, BLE vẫn giữ kết nối; sự kiện MAIN vẫn chỉ được gửi đúng một lần; sau khi mất kết nối phải có thể khôi phục theo thiết kế. | F11: P0 | G11: TC-AIV1-006 | H11: =COUNTIF('Test Cases'!$C$7:$C$175,A11) -> 4 | I11: =COUNTIFS('Test Cases'!$C$7:$C$175,A11,'Test Cases'!$O$7:$O$175,"Đạt") -> 0 | J11: =IF(H11=0,"Thiếu test case",IF(I11=H11,"Đã Đạt toàn bộ","Chưa đóng")) -> Chưa đóng
A12: GATE-G03 | B12: G03 | C12: 1. Cổng kiểm soát P0 | D12: Không xung đột giữa nhấn ngắn và nhấn giữ MAIN | E12: APP phải phân biệt được nhấn ngắn và nhấn giữ; khi đang phát âm thanh, dịch liên tục, ghi âm hoặc chờ lệnh, nhấn giữ phải dừng/tạm dừng an toàn và không nhảy sai màn hình. | F12: P0 | G12: TC-AIV1-007 | H12: =COUNTIF('Test Cases'!$C$7:$C$175,A12) -> 2 | I12: =COUNTIFS('Test Cases'!$C$7:$C$175,A12,'Test Cases'!$O$7:$O$175,"Đạt") -> 0 | J12: =IF(H12=0,"Thiếu test case",IF(I12=H12,"Đã Đạt toàn bộ","Chưa đóng")) -> Chưa đóng
A13: GATE-G04 | B13: G04 | C13: 1. Cổng kiểm soát P0 | D13: Câu lệnh giọng nói tiếng Việt có kiểm soát | E13: Sau khi bấm MAIN, trẻ em Việt Nam phải có thể dùng câu lệnh có kiểm soát để vào học theo chủ đề, học từ/câu mới và dịch; khi không hiểu thì chỉ hướng dẫn lại, không tự nhảy sai chức năng. Cần có ít nhất 1 trẻ thật ở mỗi vùng Bắc/Trung/Nam, hoặc ghi rõ phần chưa đủ mẫu. | F13: P0 | G13: TC-AIV1-008 | H13: =COUNTIF('Test Cases'!$C$7:$C$175,A13) -> 2 | I13: =COUNTIFS('Test Cases'!$C$7:$C$175,A13,'Test Cases'!$O$7:$O$175,"Đạt") -> 0 | J13: =IF(H13=0,"Thiếu test case",IF(I13=H13,"Đã Đạt toàn bộ","Chưa đóng")) -> Chưa đóng
A14: GATE-G05 | B14: G05 | C14: 1. Cổng kiểm soát P0 | D14: Kiểm soát được dịch từng câu và dịch liên tục | E14: Hai chế độ dịch từng câu và dịch liên tục đều phải khởi động và dừng được; ở chế độ liên tục, sau khoảng dừng không được nhận nhầm tiếng môi trường thành lời trẻ. | F14: P0 | G14: TC-AIV1-009 | H14: =COUNTIF('Test Cases'!$C$7:$C$175,A14) -> 2 | I14: =COUNTIFS('Test Cases'!$C$7:$C$175,A14,'Test Cases'!$O$7:$O$175,"Đạt") -> 0 | J14: =IF(H14=0,"Thiếu test case",IF(I14=H14,"Đã Đạt toàn bộ","Chưa đóng")) -> Chưa đóng
A15: GATE-G06 | B15: G06 | C15: 1. Cổng kiểm soát P0 | D15: Giọng trẻ và tiếng ồn phải sử dụng được ở mức cốt lõi | E15: Trong phòng bình thường và môi trường có tiếng ồn thường gặp, các câu ngắn quan trọng không được liên tục bị mất từ, nhảy sai chức năng hoặc thu nhầm giọng người khác. Lỗi phải được phân loại thành “nghe sai / dịch sai / trễ / phát âm thanh” và test hồi quy lại. | F15: P0 | G15: TC-AIV1-010 | H15: =COUNTIF('Test Cases'!$C$7:$C$175,A15) -> 2 | I15: =COUNTIFS('Test Cases'!$C$7:$C$175,A15,'Test Cases'!$O$7:$O$175,"Đạt") -> 0 | J15: =IF(H15=0,"Thiếu test case",IF(I15=H15,"Đã Đạt toàn bộ","Chưa đóng")) -> Chưa đóng
A16: GATE-G07 | B16: G07 | C16: 1. Cổng kiểm soát P0 | D16: Xác minh trên Android và iPhone | E16: Ít nhất 1 điện thoại Android và 1 iPhone thật phải chạy đủ chuỗi: kết nối, ghi âm, phát âm thanh, nút bấm và kết nối lại; ghi rõ mẫu máy và phiên bản hệ điều hành. Nếu chưa test iPhone thì không được ghi “tương thích iPhone”. | F16: P0 | G16: TC-AIV1-011 | H16: =COUNTIF('Test Cases'!$C$7:$C$175,A16) -> 3 | I16: =COUNTIFS('Test Cases'!$C$7:$C$175,A16,'Test Cases'!$O$7:$O$175,"Đạt") -> 0 | J16: =IF(H16=0,"Thiếu test case",IF(I16=H16,"Đã Đạt toàn bộ","Chưa đóng")) -> Chưa đóng
A17: GATE-G08 | B17: G08 | C17: 1. Cổng kiểm soát P0 | D17: Sạc và an toàn cơ bản | E17: Thiết bị mẫu phải sạc bình thường, dùng được khi đầy pin, không nóng bất thường, không có mùi lạ, phồng pin hoặc thường xuyên tắt nguồn; phải ghi lại dữ liệu sạc và thời lượng pin thực tế. | F17: P0 | G17: TC-AIV1-012 | H17: =COUNTIF('Test Cases'!$C$7:$C$175,A17) -> 3 | I17: =COUNTIFS('Test Cases'!$C$7:$C$175,A17,'Test Cases'!$O$7:$O$175,"Đạt") -> 0 | J17: =IF(H17=0,"Thiếu test case",IF(I17=H17,"Đã Đạt toàn bộ","Chưa đóng")) -> Chưa đóng
... A115: CLOSE-K06 | B115: K06 | C115: 12. Khép kín và quyết định | D115: Sếp xác nhận cuối cùng | E115: Xác nhận đã xem bằng chứng kiểm thử, đã biết các rủi ro còn lại và quyết định: làm khuôn / tạm thời chưa làm khuôn / tiếp tục xác minh. | F115: P0 | G115: TC-AIV1-110 | H115: =COUNTIF('Test Cases'!$C$7:$C$175,A115) -> 1 | I115: =COUNTIFS('Test Cases'!$C$7:$C$175,A115,'Test Cases'!$O$7:$O$175,"Đạt") -> 0 | J115: =IF(H115=0,"Thiếu test case",IF(I115=H115,"Đã Đạt toàn bộ","Chưa đóng")) -> Chưa đóng

Sheet Du lieu test
A1: DỮ LIỆU & PROFILE KIỂM THỬ | B1: DỮ LIỆU & PROFILE KIỂM THỬ | C1: DỮ LIỆU & PROFILE KIỂM THỬ | D1: DỮ LIỆU & PROFILE KIỂM THỬ | E1: DỮ LIỆU & PROFILE KIỂM THỬ | F1: DỮ LIỆU & PROFILE KIỂM THỬ | G1: DỮ LIỆU & PROFILE KIỂM THỬ
A2: Bộ dữ liệu khởi tạo; cần bổ sung giá trị thật, consent và expected mapping đã được phê duyệt trước khi chạy. | B2: Bộ dữ liệu khởi tạo; cần bổ sung giá trị thật, consent và expected mapping đã được phê duyệt trước khi chạy. | C2: Bộ dữ liệu khởi tạo; cần bổ sung giá trị thật, consent và expected mapping đã được phê duyệt trước khi chạy. | D2: Bộ dữ liệu khởi tạo; cần bổ sung giá trị thật, consent và expected mapping đã được phê duyệt trước khi chạy. | E2: Bộ dữ liệu khởi tạo; cần bổ sung giá trị thật, consent và expected mapping đã được phê duyệt trước khi chạy. | F2: Bộ dữ liệu khởi tạo; cần bổ sung giá trị thật, consent và expected mapping đã được phê duyệt trước khi chạy. | G2: Bộ dữ liệu khởi tạo; cần bổ sung giá trị thật, consent và expected mapping đã được phê duyệt trước khi chạy.
A5: Nhóm | B5: Data ID | C5: Đầu vào/Profile | D5: Thiết lập | E5: Kết quả/Oracle | F5: Áp dụng cho | G5: Ghi chú
A6: Thiết bị | B6: DEV-AND-01 | C6: Android phổ biến tại Việt Nam | D6: Điền model, RAM, Android/API, hãng | E6: Chạy đủ E2E | F6: GATE-G07, COMP-H01 | G6: Placeholder bắt buộc thay
A7: Thiết bị | B7: DEV-AND-02 | C7: Android khác hãng/OS | D7: Điền model, RAM, Android/API, hãng | E7: Chạy đủ E2E | F7: COMP-H01 | G7: Placeholder bắt buộc thay
A8: Thiết bị | B8: DEV-IOS-01 | C8: iPhone thật | D8: Điền model/iOS và build iOS | E8: Chạy đủ E2E | F8: GATE-G07, COMP-H02 | G8: APK không áp dụng
A9: Môi trường | B9: ENV-QUIET | C9: Phòng yên tĩnh | D9: Ghi dBA nền, khoảng cách, hướng nói | E9: Baseline | F9: Voice/Audio | G9: Không dùng cảm tính thay số đo nếu có thiết bị
A10: Môi trường | B10: ENV-HOME | C10: Gia đình bình thường | D10: TV nhỏ, người đi lại | E10: Không mất từ/nhầm nguồn thường xuyên | F10: Voice/Audio/UAT | G10: Ghi dBA
A11: Môi trường | B11: ENV-TV | C11: TV có lời thoại | D11: Trẻ im lặng rồi nói xen kẽ | E11: Không nhận TV là trẻ | F11: GATE-G05, VOICE-G04
A12: Môi trường | B12: ENV-ADULT | C12: Người lớn nói chen | D12: Người lớn gần/xa thiết bị | E12: Không nhận nhầm là lệnh trẻ | F12: GATE-G06, VOICE-G04
A13: Môi trường | B13: ENV-CLASS | C13: Tiếng lớp học | D13: Nhiều giọng và chuyển động | E13: Câu cốt lõi vẫn dùng được | F13: HW-C08, VOICE-G04 | G13: Ghi dBA
A14: Mạng | B14: NET-WIFI | C14: Wi-Fi tốt | D14: Ghi latency/bandwidth/loss | E14: Baseline | F14: E06/H05
A15: Mạng | B15: NET-MOBILE | C15: Dữ liệu di động | D15: Ghi nhà mạng và signal | E15: So sánh Wi-Fi | F15: A05/E06
A16: Mạng | B16: NET-WEAK | C16: Mạng yếu | D16: Ngưỡng cần QA phê duyệt | E16: Thông báo/retry rõ | F16: A05/E07/H06
A17: Mạng | B17: NET-OFFLINE | C17: Mất mạng hoàn toàn | D17: Tắt cả Wi-Fi/mobile | E17: Không báo thành công; không quay vô hạn | F17: E07/H06
A18: Mạng | B18: NET-RECOVERY | C18: Mất rồi có lại giữa giao dịch | D18: Khôi phục sau 10-30 giây | E18: Tiếp tục được; không trùng dữ liệu | F18: H06
A19: Bluetooth | B19: BT-PAIR | C19: Find/pair/unpair/re-pair | D19: Android + iPhone | E19: Tên rõ; không nhầm thiết bị | F19: B01
A20: Bluetooth | B20: BT-HFP-MIC | C20: Đối chứng nguồn micro | D20: Che micro phone/đặt xa/đưa thiết bị gần | E20: Audio input từ thiết bị | F20: GATE-G01/B02
A21: Bluetooth | B21: BT-HFP-SPK | C21: Đối chứng nguồn loa | D21: Che loa phone/đổi volume | E21: TTS từ loa thiết bị | F21: GATE-G01/B03
A22: Bluetooth | B22: BT-RECONNECT | C22: BT off/on, out-of-range, background | D22: Tách thời gian HFP và BLE | E22: Phục hồi theo thiết kế | F22: G02/B10
A23: Lệnh | B23: CMD-LEARN-01 | C23: Học bài | D23: Nhấn MAIN rồi nói | E23: Intent học theo chủ đề | F23: G04/D04
A24: Lệnh | B24: CMD-LEARN-02 | C24: Học theo chủ đề | D24: Nhấn MAIN rồi nói | E24: Intent học theo chủ đề | F24: G04/D04
A25: Lệnh | B25: CMD-LEARN-03 | C25: Học khóa học | D25: Nhấn MAIN rồi nói | E25: Intent học theo chủ đề | F25: D04
... A39: Negative | B39: NEG-LOW-CONF | C39: Nói nhỏ/không rõ | D39: Giữ audio để phân tích | E39: Hướng dẫn nói lại | F39: D03
A40: Dịch | B40: TR-CORE-01 | C40: Mẹ ơi, con muốn mua cái này | D40: Giọng trẻ, một câu | E40: Giữ xưng hô và nhu cầu | F40: E02/G07 | G40: Case nguồn điển hình
A41: Dịch | B41: TR-CORE-02 | C41: Con không muốn ăn món này | D41: Kiểm tra phủ định | E41: Giữ chủ ngữ và phủ định | F41: E02
A42: Dịch | B42: TR-CORE-03 | C42: Bố ơi, con cần đi vệ sinh | D42: Kiểm tra xưng hô/nhu cầu | E42: Ngắn, an toàn, đúng nghĩa | F42: E02
A43: Dịch | B43: TR-CORE-04 | C43: Con bị đau ở đây | D43: Ngữ cảnh nhạy cảm | E43: Không thêm/chẩn đoán sai | F43: E02/F10 | G43: Cần policy nội dung
A44: Dịch | B44: TR-SLOW-01 | C44: Mẹ ơi... con muốn... mua cái này | D44: Dừng 0,5-2 giây | E44: Không cắt sớm | F44: E05
A45: Tuổi | B45: AGE-LOW | C45: Tuổi thấp nhất hỗ trợ | D45: Theo định nghĩa sản phẩm | E45: Nội dung phù hợp | F45: F01 | G45: Cần PO xác nhận
A46: Tuổi | B46: AGE-BOUNDARY | C46: Tuổi tại ranh giới hai nhóm | D46: Test hai phía ranh giới | E46: Mapping nhất quán | F46: F01 | G46: Cần PO xác nhận
A47: Tuổi | B47: AGE-HIGH | C47: Tuổi cao nhất hỗ trợ | D47: Theo định nghĩa sản phẩm | E47: Nội dung phù hợp | F47: F01 | G47: Cần PO xác nhận
A48: Nội dung | B48: CONTENT-WORD | C48: Một từ đơn phổ biến | D48: Phụ huynh thêm | E48: Khớp câu đã duyệt | F48: F07/F08
A49: Nội dung | B49: CONTENT-UNKNOWN-01 | C49: Từ hiếm không có trong kho | D49: Phụ huynh thêm | E49: Chờ xác nhận, không tự sinh sai | F49: F08
A50: An toàn | B50: SAFE-PROFANITY | C50: Từ tục/xúc phạm | D50: Dùng dữ liệu giả lập tối thiểu | E50: Chặn/phản hồi an toàn | F50: F10 | G50: Không lưu trong tài liệu chia sẻ rộng
A51: An toàn | B51: SAFE-SEXUAL | C51: Nội dung tình dục | D51: Dữ liệu kiểm soát | E51: Không đưa tới trẻ | F51: F10
A52: An toàn | B52: SAFE-VIOLENCE | C52: Nội dung bạo lực/đẫm máu | D52: Dữ liệu kiểm soát | E52: Không đưa tới trẻ | F52: F10
A53: Voice cohort | B53: VOICE-B/N/T | C53: Mẫu Bắc/Trung/Nam | D53: Mã ẩn danh + consent | E53: Kết quả tách theo vùng | F53: G01-G04 | G53: Không ghi PII
A54: Interrupt | B54: INT-BG | C54: App background/foreground | D54: 60 giây | E54: Phục hồi rõ | F54: H03
A55: Interrupt | B55: INT-LOCK | C55: Khóa/mở màn hình | D55: 30 giây | E55: Không lỗi im lặng | F55: H03
...

Sheet Defect Log
A1: DEFECT LOG | B1: DEFECT LOG | C1: DEFECT LOG | D1: DEFECT LOG | E1: DEFECT LOG | F1: DEFECT LOG | G1: DEFECT LOG | H1: DEFECT LOG | I1: DEFECT LOG | J1: DEFECT LOG | K1: DEFECT LOG | L1: DEFECT LOG | M1: DEFECT LOG | N1: DEFECT LOG | O1: DEFECT LOG
A2: Mọi test case Không đạt phải có Defect ID, bước tái hiện, môi trường, bằng chứng và owner. Không dùng mô tả chung chung như 'dịch không chính xác'. | B2: Mọi test case Không đạt phải có Defect ID, bước tái hiện, môi trường, bằng chứng và owner. Không dùng mô tả chung chung như 'dịch không chính xác'. | C2: Mọi test case Không đạt phải có Defect ID, bước tái hiện, môi trường, bằng chứng và owner. Không dùng mô tả chung chung như 'dịch không chính xác'. | D2: Mọi test case Không đạt phải có Defect ID, bước tái hiện, môi trường, bằng chứng và owner. Không dùng mô tả chung chung như 'dịch không chính xác'. | E2: Mọi test case Không đạt phải có Defect ID, bước tái hiện, môi trường, bằng chứng và owner. Không dùng mô tả chung chung như 'dịch không chính xác'. | F2: Mọi test case Không đạt phải có Defect ID, bước tái hiện, môi trường, bằng chứng và owner. Không dùng mô tả chung chung như 'dịch không chính xác'. | G2: Mọi test case Không đạt phải có Defect ID, bước tái hiện, môi trường, bằng chứng và owner. Không dùng mô tả chung chung như 'dịch không chính xác'. | H2: Mọi test case Không đạt phải có Defect ID, bước tái hiện, môi trường, bằng chứng và owner. Không dùng mô tả chung chung như 'dịch không chính xác'. | I2: Mọi test case Không đạt phải có Defect ID, bước tái hiện, môi trường, bằng chứng và owner. Không dùng mô tả chung chung như 'dịch không chính xác'. | J2: Mọi test case Không đạt phải có Defect ID, bước tái hiện, môi trường, bằng chứng và owner. Không dùng mô tả chung chung như 'dịch không chính xác'. | K2: Mọi test case Không đạt phải có Defect ID, bước tái hiện, môi trường, bằng chứng và owner. Không dùng mô tả chung chung như 'dịch không chính xác'. | L2: Mọi test case Không đạt phải có Defect ID, bước tái hiện, môi trường, bằng chứng và owner. Không dùng mô tả chung chung như 'dịch không chính xác'. | M2: Mọi test case Không đạt phải có Defect ID, bước tái hiện, môi trường, bằng chứng và owner. Không dùng mô tả chung chung như 'dịch không chính xác'. | N2: Mọi test case Không đạt phải có Defect ID, bước tái hiện, môi trường, bằng chứng và owner. Không dùng mô tả chung chung như 'dịch không chính xác'. | O2: Mọi test case Không đạt phải có Defect ID, bước tái hiện, môi trường, bằng chứng và owner. Không dùng mô tả chung chung như 'dịch không chính xác'.
A5: Defect ID | B5: Related TC | C5: Requirement | D5: Tóm tắt | E5: Severity | F5: Priority | G5: Status | H5: Repro rate | I5: Môi trường | J5: Bước tái hiện | K5: Actual | L5: Expected | M5: Evidence | N5: Owner | O5: Target date
